2025-11-17T09:33:53.142963965Z W1117 09:33:53.142861       1 feature_gate.go:227] unrecognized feature gate: InsightsConfigAPI
2025-11-17T09:33:53.142963965Z W1117 09:33:53.142930       1 feature_gate.go:227] unrecognized feature gate: OpenShiftPodSecurityAdmission
2025-11-17T09:33:53.142963965Z W1117 09:33:53.142934       1 feature_gate.go:227] unrecognized feature gate: AzureWorkloadIdentity
2025-11-17T09:33:53.142963965Z W1117 09:33:53.142937       1 feature_gate.go:227] unrecognized feature gate: BuildCSIVolumes
2025-11-17T09:33:53.142963965Z W1117 09:33:53.142940       1 feature_gate.go:227] unrecognized feature gate: CSIDriverSharedResource
2025-11-17T09:33:53.142963965Z W1117 09:33:53.142944       1 feature_gate.go:227] unrecognized feature gate: ExternalCloudProviderExternal
2025-11-17T09:33:53.142963965Z W1117 09:33:53.142947       1 feature_gate.go:227] unrecognized feature gate: NetworkLiveMigration
2025-11-17T09:33:53.142963965Z W1117 09:33:53.142951       1 feature_gate.go:227] unrecognized feature gate: AdminNetworkPolicy
2025-11-17T09:33:53.142963965Z W1117 09:33:53.142954       1 feature_gate.go:227] unrecognized feature gate: ExternalCloudProvider
2025-11-17T09:33:53.142963965Z W1117 09:33:53.142957       1 feature_gate.go:227] unrecognized feature gate: MachineAPIOperatorDisableMachineHealthCheckController
2025-11-17T09:33:53.142963965Z W1117 09:33:53.142960       1 feature_gate.go:227] unrecognized feature gate: SigstoreImageVerification
2025-11-17T09:33:53.143055287Z W1117 09:33:53.142963       1 feature_gate.go:227] unrecognized feature gate: AutomatedEtcdBackup
2025-11-17T09:33:53.143055287Z W1117 09:33:53.142966       1 feature_gate.go:227] unrecognized feature gate: MachineAPIProviderOpenStack
2025-11-17T09:33:53.143055287Z W1117 09:33:53.142969       1 feature_gate.go:227] unrecognized feature gate: PrivateHostedZoneAWS
2025-11-17T09:33:53.143055287Z W1117 09:33:53.142972       1 feature_gate.go:227] unrecognized feature gate: RouteExternalCertificate
2025-11-17T09:33:53.143055287Z W1117 09:33:53.142975       1 feature_gate.go:227] unrecognized feature gate: AlibabaPlatform
2025-11-17T09:33:53.143055287Z W1117 09:33:53.142978       1 feature_gate.go:227] unrecognized feature gate: ExternalCloudProviderAzure
2025-11-17T09:33:53.143055287Z W1117 09:33:53.142981       1 feature_gate.go:227] unrecognized feature gate: GCPLabelsTags
2025-11-17T09:33:53.143055287Z W1117 09:33:53.142984       1 feature_gate.go:227] unrecognized feature gate: ExternalCloudProviderGCP
2025-11-17T09:33:53.143055287Z W1117 09:33:53.142987       1 feature_gate.go:227] unrecognized feature gate: VSphereStaticIPs
2025-11-17T09:33:53.143055287Z W1117 09:33:53.142990       1 feature_gate.go:227] unrecognized feature gate: GatewayAPI
2025-11-17T09:33:53.143063051Z I1117 09:33:53.143054       1 flags.go:64] FLAG: --allow-metric-labels="[]"
2025-11-17T09:33:53.143067353Z I1117 09:33:53.143061       1 flags.go:64] FLAG: --authentication-kubeconfig="/etc/kubernetes/static-pod-resources/configmaps/scheduler-kubeconfig/kubeconfig"
2025-11-17T09:33:53.143168601Z I1117 09:33:53.143158       1 flags.go:64] FLAG: --authentication-skip-lookup="false"
2025-11-17T09:33:53.143168601Z I1117 09:33:53.143164       1 flags.go:64] FLAG: --authentication-token-webhook-cache-ttl="10s"
2025-11-17T09:33:53.143173843Z I1117 09:33:53.143168       1 flags.go:64] FLAG: --authentication-tolerate-lookup-failure="true"
2025-11-17T09:33:53.143178113Z I1117 09:33:53.143171       1 flags.go:64] FLAG: --authorization-always-allow-paths="[/healthz,/readyz,/livez]"
2025-11-17T09:33:53.143182220Z I1117 09:33:53.143175       1 flags.go:64] FLAG: --authorization-kubeconfig="/etc/kubernetes/static-pod-resources/configmaps/scheduler-kubeconfig/kubeconfig"
2025-11-17T09:33:53.143182220Z I1117 09:33:53.143180       1 flags.go:64] FLAG: --authorization-webhook-cache-authorized-ttl="10s"
2025-11-17T09:33:53.143192794Z I1117 09:33:53.143183       1 flags.go:64] FLAG: --authorization-webhook-cache-unauthorized-ttl="10s"
2025-11-17T09:33:53.143196989Z I1117 09:33:53.143185       1 flags.go:64] FLAG: --bind-address="0.0.0.0"
2025-11-17T09:33:53.143201053Z I1117 09:33:53.143197       1 flags.go:64] FLAG: --cert-dir="/var/run/kubernetes"
2025-11-17T09:33:53.143205137Z I1117 09:33:53.143200       1 flags.go:64] FLAG: --client-ca-file=""
2025-11-17T09:33:53.143205137Z I1117 09:33:53.143203       1 flags.go:64] FLAG: --config="/etc/kubernetes/static-pod-resources/configmaps/config/config.yaml"
2025-11-17T09:33:53.143209369Z I1117 09:33:53.143205       1 flags.go:64] FLAG: --contention-profiling="true"
2025-11-17T09:33:53.143234316Z I1117 09:33:53.143208       1 flags.go:64] FLAG: --disabled-metrics="[]"
2025-11-17T09:33:53.143252796Z I1117 09:33:53.143230       1 flags.go:64] FLAG: --feature-gates="AdmissionWebhookMatchConditions=false,CloudDualStackNodeIPs=true,DynamicResourceAllocation=false,EventedPLEG=false,MaxUnavailableStatefulSet=false,NodeSwap=false,RetroactiveDefaultStorageClass=false,ValidatingAdmissionPolicy=false"
2025-11-17T09:33:53.143252796Z I1117 09:33:53.143248       1 flags.go:64] FLAG: --help="false"
2025-11-17T09:33:53.143257563Z I1117 09:33:53.143251       1 flags.go:64] FLAG: --http2-max-streams-per-connection="0"
2025-11-17T09:33:53.143257563Z I1117 09:33:53.143254       1 flags.go:64] FLAG: --kube-api-burst="100"
2025-11-17T09:33:53.143267810Z I1117 09:33:53.143257       1 flags.go:64] FLAG: --kube-api-content-type="application/vnd.kubernetes.protobuf"
2025-11-17T09:33:53.143278373Z I1117 09:33:53.143267       1 flags.go:64] FLAG: --kube-api-qps="50"
2025-11-17T09:33:53.143278373Z I1117 09:33:53.143275       1 flags.go:64] FLAG: --kubeconfig=""
2025-11-17T09:33:53.143282960Z I1117 09:33:53.143277       1 flags.go:64] FLAG: --leader-elect="true"
2025-11-17T09:33:53.143282960Z I1117 09:33:53.143280       1 flags.go:64] FLAG: --leader-elect-lease-duration="15s"
2025-11-17T09:33:53.143287113Z I1117 09:33:53.143282       1 flags.go:64] FLAG: --leader-elect-renew-deadline="10s"
2025-11-17T09:33:53.143287113Z I1117 09:33:53.143284       1 flags.go:64] FLAG: --leader-elect-resource-lock="leases"
2025-11-17T09:33:53.143291395Z I1117 09:33:53.143287       1 flags.go:64] FLAG: --leader-elect-resource-name="kube-scheduler"
2025-11-17T09:33:53.143291395Z I1117 09:33:53.143289       1 flags.go:64] FLAG: --leader-elect-resource-namespace="kube-system"
2025-11-17T09:33:53.143295889Z I1117 09:33:53.143291       1 flags.go:64] FLAG: --leader-elect-retry-period="2s"
2025-11-17T09:33:53.143295889Z I1117 09:33:53.143294       1 flags.go:64] FLAG: --lock-object-name="kube-scheduler"
2025-11-17T09:33:53.143300109Z I1117 09:33:53.143296       1 flags.go:64] FLAG: --lock-object-namespace="kube-system"
2025-11-17T09:33:53.143300109Z I1117 09:33:53.143298       1 flags.go:64] FLAG: --log-flush-frequency="5s"
2025-11-17T09:33:53.143310963Z I1117 09:33:53.143300       1 flags.go:64] FLAG: --log-json-info-buffer-size="0"
2025-11-17T09:33:53.143310963Z I1117 09:33:53.143307       1 flags.go:64] FLAG: --log-json-split-stream="false"
2025-11-17T09:33:53.143315424Z I1117 09:33:53.143310       1 flags.go:64] FLAG: --logging-format="text"
2025-11-17T09:33:53.143315424Z I1117 09:33:53.143312       1 flags.go:64] FLAG: --XXXXXX=""
2025-11-17T09:33:53.143319723Z I1117 09:33:53.143315       1 flags.go:64] FLAG: --permit-address-sharing="false"
2025-11-17T09:33:53.143319723Z I1117 09:33:53.143317       1 flags.go:64] FLAG: --permit-port-sharing="false"
2025-11-17T09:33:53.143326389Z I1117 09:33:53.143320       1 flags.go:64] FLAG: --pod-max-in-unschedulable-pods-duration="5m0s"
2025-11-17T09:33:53.143326389Z I1117 09:33:53.143322       1 flags.go:64] FLAG: --profiling="true"
2025-11-17T09:33:53.143330639Z I1117 09:33:53.143324       1 flags.go:64] FLAG: --requestheader-allowed-names="[]"
2025-11-17T09:33:53.143330639Z I1117 09:33:53.143327       1 flags.go:64] FLAG: --requestheader-client-ca-file=""
2025-11-17T09:33:53.143334891Z I1117 09:33:53.143330       1 flags.go:64] FLAG: --requestheader-extra-headers-prefix="[x-remote-extra-]"
2025-11-17T09:33:53.143342903Z I1117 09:33:53.143333       1 flags.go:64] FLAG: --requestheader-group-headers="[x-remote-group]"
2025-11-17T09:33:53.143342903Z I1117 09:33:53.143336       1 flags.go:64] FLAG: --requestheader-username-headers="[x-remote-user]"
2025-11-17T09:33:53.143342903Z I1117 09:33:53.143339       1 flags.go:64] FLAG: --secure-port="10259"
2025-11-17T09:33:53.143348055Z I1117 09:33:53.143342       1 flags.go:64] FLAG: --show-hidden-metrics-for-version=""
2025-11-17T09:33:53.143437715Z I1117 09:33:53.143344       1 flags.go:64] FLAG: --tls-cert-file="/etc/kubernetes/static-pod-resources/secrets/serving-cert/tls.crt"
2025-11-17T09:33:53.143444003Z I1117 09:33:53.143433       1 flags.go:64] FLAG: --tls-cipher-suites="[TLS_ECDHE_ECDSA_WITH_AES_128_GCM_SHA256,TLS_ECDHE_RSA_WITH_AES_128_GCM_SHA256,TLS_ECDHE_ECDSA_WITH_AES_256_GCM_SHA384,TLS_ECDHE_RSA_WITH_AES_256_GCM_SHA384,TLS_ECDHE_ECDSA_WITH_CHACHA20_POLY1305_SHA256,TLS_ECDHE_RSA_WITH_CHACHA20_POLY1305_SHA256]"
2025-11-17T09:33:53.143444003Z I1117 09:33:53.143441       1 flags.go:64] FLAG: --tls-min-version="VersionTLS12"
2025-11-17T09:33:53.143448261Z I1117 09:33:53.143443       1 flags.go:64] FLAG: --tls-private-key-file="/etc/kubernetes/static-pod-resources/secrets/serving-cert/tls.key"
2025-11-17T09:33:53.143452328Z I1117 09:33:53.143447       1 flags.go:64] FLAG: --tls-sni-cert-key="[]"
2025-11-17T09:33:53.143452328Z I1117 09:33:53.143450       1 flags.go:64] FLAG: --unsupported-kube-api-over-localhost="false"
2025-11-17T09:33:53.143467345Z I1117 09:33:53.143456       1 flags.go:64] FLAG: --v="2"
2025-11-17T09:33:53.143467345Z I1117 09:33:53.143464       1 flags.go:64] FLAG: --version="false"
2025-11-17T09:33:53.143471941Z I1117 09:33:53.143468       1 flags.go:64] FLAG: --vmodule=""
2025-11-17T09:33:53.143476012Z I1117 09:33:53.143471       1 flags.go:64] FLAG: --write-config-to=""
2025-11-17T09:33:53.144315586Z I1117 09:33:53.144294       1 configfile.go:59] "KubeSchedulerConfiguration v1beta3 is deprecated in v1.26, will be removed in v1.29"
2025-11-17T09:33:53.145812817Z I1117 09:33:53.145786       1 dynamic_serving_content.go:113] "Loaded a new cert/key pair" name="serving-cert::/etc/kubernetes/static-pod-resources/secrets/serving-cert/tls.crt::/etc/kubernetes/static-pod-resources/secrets/serving-cert/tls.key"
2025-11-17T09:33:53.684669945Z I1117 09:33:53.684597       1 requestheader_controller.go:244] Loaded a new request header values for RequestHeaderAuthRequestController
2025-11-17T09:33:53.697273609Z I1117 09:33:53.697213       1 configfile.go:105] "Using component config" config=<
2025-11-17T09:33:53.697273609Z 	apiVersion: kubescheduler.config.k8s.io/v1beta3
2025-11-17T09:33:53.697273609Z 	clientConnection:
2025-11-17T09:33:53.697273609Z 	  acceptContentTypes: ""
2025-11-17T09:33:53.697273609Z 	  burst: 100
2025-11-17T09:33:53.697273609Z 	  contentType: application/vnd.kubernetes.protobuf
2025-11-17T09:33:53.697273609Z 	  kubeconfig: /etc/kubernetes/static-pod-resources/configmaps/scheduler-kubeconfig/kubeconfig
2025-11-17T09:33:53.697273609Z 	  qps: 50
2025-11-17T09:33:53.697273609Z 	enableContentionProfiling: false
2025-11-17T09:33:53.697273609Z 	enableProfiling: false
2025-11-17T09:33:53.697273609Z 	kind: KubeSchedulerConfiguration
2025-11-17T09:33:53.697273609Z 	leaderElection:
2025-11-17T09:33:53.697273609Z 	  leaderElect: true
2025-11-17T09:33:53.697273609Z 	  leaseDuration: 2m17s
2025-11-17T09:33:53.697273609Z 	  renewDeadline: 1m47s
2025-11-17T09:33:53.697273609Z 	  resourceLock: leases
2025-11-17T09:33:53.697273609Z 	  resourceName: kube-scheduler
2025-11-17T09:33:53.697273609Z 	  resourceNamespace: openshift-kube-scheduler
2025-11-17T09:33:53.697273609Z 	  retryPeriod: 26s
2025-11-17T09:33:53.697273609Z 	parallelism: 16
2025-11-17T09:33:53.697273609Z 	percentageOfNodesToScore: 0
2025-11-17T09:33:53.697273609Z 	podInitialBackoffSeconds: 1
2025-11-17T09:33:53.697273609Z 	podMaxBackoffSeconds: 10
2025-11-17T09:33:53.697273609Z 	profiles:
2025-11-17T09:33:53.697273609Z 	- pluginConfig:
2025-11-17T09:33:53.697273609Z 	  - args:
2025-11-17T09:33:53.697273609Z 	      apiVersion: kubescheduler.config.k8s.io/v1beta3
2025-11-17T09:33:53.697273609Z 	      kind: DefaultPreemptionArgs
2025-11-17T09:33:53.697273609Z 	      minCandidateNodesAbsolute: 100
2025-11-17T09:33:53.697273609Z 	      minCandidateNodesPercentage: 10
2025-11-17T09:33:53.697273609Z 	    name: DefaultPreemption
2025-11-17T09:33:53.697273609Z 	  - args:
2025-11-17T09:33:53.697273609Z 	      apiVersion: kubescheduler.config.k8s.io/v1beta3
2025-11-17T09:33:53.697273609Z 	      hardPodAffinityWeight: 1
2025-11-17T09:33:53.697273609Z 	      ignorePreferredTermsOfExistingPods: false
2025-11-17T09:33:53.697273609Z 	      kind: InterPodAffinityArgs
2025-11-17T09:33:53.697273609Z 	    name: InterPodAffinity
2025-11-17T09:33:53.697273609Z 	  - args:
2025-11-17T09:33:53.697273609Z 	      apiVersion: kubescheduler.config.k8s.io/v1beta3
2025-11-17T09:33:53.697273609Z 	      kind: NodeAffinityArgs
2025-11-17T09:33:53.697273609Z 	    name: NodeAffinity
2025-11-17T09:33:53.697273609Z 	  - args:
2025-11-17T09:33:53.697273609Z 	      apiVersion: kubescheduler.config.k8s.io/v1beta3
2025-11-17T09:33:53.697273609Z 	      kind: NodeResourcesBalancedAllocationArgs
2025-11-17T09:33:53.697273609Z 	      resources:
2025-11-17T09:33:53.697273609Z 	      - name: cpu
2025-11-17T09:33:53.697273609Z 	        weight: 1
2025-11-17T09:33:53.697273609Z 	      - name: memory
2025-11-17T09:33:53.697273609Z 	        weight: 1
2025-11-17T09:33:53.697273609Z 	    name: NodeResourcesBalancedAllocation
2025-11-17T09:33:53.697273609Z 	  - args:
2025-11-17T09:33:53.697273609Z 	      apiVersion: kubescheduler.config.k8s.io/v1beta3
2025-11-17T09:33:53.697273609Z 	      kind: NodeResourcesFitArgs
2025-11-17T09:33:53.697273609Z 	      scoringStrategy:
2025-11-17T09:33:53.697273609Z 	        resources:
2025-11-17T09:33:53.697273609Z 	        - name: cpu
2025-11-17T09:33:53.697273609Z 	          weight: 1
2025-11-17T09:33:53.697273609Z 	        - name: memory
2025-11-17T09:33:53.697273609Z 	          weight: 1
2025-11-17T09:33:53.697273609Z 	        type: LeastAllocated
2025-11-17T09:33:53.697273609Z 	    name: NodeResourcesFit
2025-11-17T09:33:53.697273609Z 	  - args:
2025-11-17T09:33:53.697273609Z 	      apiVersion: kubescheduler.config.k8s.io/v1beta3
2025-11-17T09:33:53.697273609Z 	      defaultingType: System
2025-11-17T09:33:53.697273609Z 	      kind: PodTopologySpreadArgs
2025-11-17T09:33:53.697273609Z 	    name: PodTopologySpread
2025-11-17T09:33:53.697273609Z 	  - args:
2025-11-17T09:33:53.697273609Z 	      apiVersion: kubescheduler.config.k8s.io/v1beta3
2025-11-17T09:33:53.697273609Z 	      bindTimeoutSeconds: 600
2025-11-17T09:33:53.697273609Z 	      kind: VolumeBindingArgs
2025-11-17T09:33:53.697273609Z 	    name: VolumeBinding
2025-11-17T09:33:53.697273609Z 	  plugins:
2025-11-17T09:33:53.697273609Z 	    bind: {}
2025-11-17T09:33:53.697273609Z 	    filter: {}
2025-11-17T09:33:53.697273609Z 	    multiPoint:
2025-11-17T09:33:53.697273609Z 	      enabled:
2025-11-17T09:33:53.697273609Z 	      - name: PrioritySort
2025-11-17T09:33:53.697273609Z 	        weight: 0
2025-11-17T09:33:53.697273609Z 	      - name: NodeUnschedulable
2025-11-17T09:33:53.697273609Z 	        weight: 0
2025-11-17T09:33:53.697273609Z 	      - name: NodeName
2025-11-17T09:33:53.697273609Z 	        weight: 0
2025-11-17T09:33:53.697273609Z 	      - name: TaintToleration
2025-11-17T09:33:53.697273609Z 	        weight: 3
2025-11-17T09:33:53.697273609Z 	      - name: NodeAffinity
2025-11-17T09:33:53.697273609Z 	        weight: 2
2025-11-17T09:33:53.697273609Z 	      - name: NodePorts
2025-11-17T09:33:53.697273609Z 	        weight: 0
2025-11-17T09:33:53.697273609Z 	      - name: NodeResourcesFit
2025-11-17T09:33:53.697273609Z 	        weight: 1
2025-11-17T09:33:53.697273609Z 	      - name: VolumeRestrictions
2025-11-17T09:33:53.697273609Z 	        weight: 0
2025-11-17T09:33:53.697273609Z 	      - name: EBSLimits
2025-11-17T09:33:53.697273609Z 	        weight: 0
2025-11-17T09:33:53.697273609Z 	      - name: GCEPDLimits
2025-11-17T09:33:53.697273609Z 	        weight: 0
2025-11-17T09:33:53.697273609Z 	      - name: NodeVolumeLimits
2025-11-17T09:33:53.697273609Z 	        weight: 0
2025-11-17T09:33:53.697273609Z 	      - name: AzureDiskLimits
2025-11-17T09:33:53.697273609Z 	        weight: 0
2025-11-17T09:33:53.697273609Z 	      - name: VolumeBinding
2025-11-17T09:33:53.697273609Z 	        weight: 0
2025-11-17T09:33:53.697273609Z 	      - name: VolumeZone
2025-11-17T09:33:53.697273609Z 	        weight: 0
2025-11-17T09:33:53.697273609Z 	      - name: PodTopologySpread
2025-11-17T09:33:53.697273609Z 	        weight: 2
2025-11-17T09:33:53.697273609Z 	      - name: InterPodAffinity
2025-11-17T09:33:53.697273609Z 	        weight: 2
2025-11-17T09:33:53.697273609Z 	      - name: DefaultPreemption
2025-11-17T09:33:53.697273609Z 	        weight: 0
2025-11-17T09:33:53.697273609Z 	      - name: NodeResourcesBalancedAllocation
2025-11-17T09:33:53.697273609Z 	        weight: 1
2025-11-17T09:33:53.697273609Z 	      - name: ImageLocality
2025-11-17T09:33:53.697273609Z 	        weight: 1
2025-11-17T09:33:53.697273609Z 	      - name: DefaultBinder
2025-11-17T09:33:53.697273609Z 	        weight: 0
2025-11-17T09:33:53.697273609Z 	      - name: SchedulingGates
2025-11-17T09:33:53.697273609Z 	        weight: 0
2025-11-17T09:33:53.697273609Z 	    permit: {}
2025-11-17T09:33:53.697273609Z 	    postBind: {}
2025-11-17T09:33:53.697273609Z 	    postFilter: {}
2025-11-17T09:33:53.697273609Z 	    preBind: {}
2025-11-17T09:33:53.697273609Z 	    preEnqueue: {}
2025-11-17T09:33:53.697273609Z 	    preFilter: {}
2025-11-17T09:33:53.697273609Z 	    preScore: {}
2025-11-17T09:33:53.697273609Z 	    queueSort: {}
2025-11-17T09:33:53.697273609Z 	    reserve: {}
2025-11-17T09:33:53.697273609Z 	    score: {}
2025-11-17T09:33:53.697273609Z 	  schedulerName: default-scheduler
2025-11-17T09:33:53.697273609Z  >
2025-11-17T09:33:53.697484061Z I1117 09:33:53.697465       1 server.go:159] "Starting Kubernetes Scheduler" version="v1.27.16+03a907c"
2025-11-17T09:33:53.697484061Z I1117 09:33:53.697480       1 server.go:161] "Golang settings" GOGC="" GOMAXPROCS="" GOTRACEBACK=""
2025-11-17T09:33:53.701022422Z I1117 09:33:53.700871       1 requestheader_controller.go:169] Starting RequestHeaderAuthRequestController
2025-11-17T09:33:53.701022422Z I1117 09:33:53.700915       1 configmap_cafile_content.go:202] "Starting controller" name="client-ca::kube-system::extension-apiserver-authentication::client-ca-file"
2025-11-17T09:33:53.701022422Z I1117 09:33:53.700923       1 shared_informer.go:311] Waiting for caches to sync for RequestHeaderAuthRequestController
2025-11-17T09:33:53.701022422Z I1117 09:33:53.700933       1 shared_informer.go:311] Waiting for caches to sync for client-ca::kube-system::extension-apiserver-authentication::client-ca-file
2025-11-17T09:33:53.701022422Z I1117 09:33:53.701004       1 configmap_cafile_content.go:202] "Starting controller" name="client-ca::kube-system::extension-apiserver-authentication::requestheader-client-ca-file"
2025-11-17T09:33:53.701044387Z I1117 09:33:53.701024       1 shared_informer.go:311] Waiting for caches to sync for client-ca::kube-system::extension-apiserver-authentication::requestheader-client-ca-file
2025-11-17T09:33:53.701408517Z I1117 09:33:53.701388       1 dynamic_serving_content.go:132] "Starting controller" name="serving-cert::/etc/kubernetes/static-pod-resources/secrets/serving-cert/tls.crt::/etc/kubernetes/static-pod-resources/secrets/serving-cert/tls.key"
2025-11-17T09:33:53.701785677Z I1117 09:33:53.701764       1 tlsconfig.go:200] "Loaded serving cert" certName="serving-cert::/etc/kubernetes/static-pod-resources/secrets/serving-cert/tls.crt::/etc/kubernetes/static-pod-resources/secrets/serving-cert/tls.key" certDetail="\"scheduler.openshift-kube-scheduler.svc\" [serving] validServingFor=[scheduler.openshift-kube-scheduler.svc,scheduler.openshift-kube-scheduler.svc.cluster.local] issuer=\"openshift-service-serving-signer@1763371220\" (2025-11-17 09:20:36 +0000 UTC to 2027-11-17 09:20:37 +0000 UTC (now=2025-11-17 09:33:53.701715951 +0000 UTC))"
2025-11-17T09:33:53.702251627Z I1117 09:33:53.702235       1 named_certificates.go:53] "Loaded SNI cert" index=0 certName="self-signed loopback" certDetail="\"apiserver-loopback-client@1763372033\" [serving] validServingFor=[apiserver-loopback-client] issuer=\"apiserver-loopback-client-ca@1763372033\" (2025-11-17 08:33:53 +0000 UTC to 2026-11-17 08:33:53 +0000 UTC (now=2025-11-17 09:33:53.702214487 +0000 UTC))"
2025-11-17T09:33:53.702285757Z I1117 09:33:53.702275       1 secure_serving.go:213] Serving securely on [::]:10259
2025-11-17T09:33:53.702344054Z I1117 09:33:53.702334       1 tlsconfig.go:240] "Starting DynamicServingCertificateController"
2025-11-17T09:33:53.732917106Z I1117 09:33:53.732858       1 node_tree.go:65] "Added node in listed group to NodeTree" node="XXXXXX0" zone=""
2025-11-17T09:33:53.732917106Z I1117 09:33:53.732904       1 node_tree.go:65] "Added node in listed group to NodeTree" node="XXXXXX1" zone=""
2025-11-17T09:33:53.733007486Z I1117 09:33:53.732993       1 node_tree.go:65] "Added node in listed group to NodeTree" node="XXXXXX2" zone=""
2025-11-17T09:33:53.733036566Z I1117 09:33:53.733028       1 node_tree.go:65] "Added node in listed group to NodeTree" node="XXXXXX0" zone=""
2025-11-17T09:33:53.733042581Z I1117 09:33:53.733039       1 node_tree.go:65] "Added node in listed group to NodeTree" node="XXXXXX1" zone=""
2025-11-17T09:33:53.801926532Z I1117 09:33:53.801783       1 shared_informer.go:318] Caches are synced for client-ca::kube-system::extension-apiserver-authentication::client-ca-file
2025-11-17T09:33:53.802042658Z I1117 09:33:53.802015       1 shared_informer.go:318] Caches are synced for client-ca::kube-system::extension-apiserver-authentication::requestheader-client-ca-file
2025-11-17T09:33:53.802042658Z I1117 09:33:53.802026       1 shared_informer.go:318] Caches are synced for RequestHeaderAuthRequestController
2025-11-17T09:33:53.802210866Z I1117 09:33:53.802189       1 tlsconfig.go:178] "Loaded client CA" index=0 certName="client-ca::kube-system::extension-apiserver-authentication::client-ca-file,client-ca::kube-system::extension-apiserver-authentication::requestheader-client-ca-file" certDetail="\"admin-kubeconfig-signer\" [] issuer=\"<self>\" (2025-11-17 08:23:44 +0000 UTC to 2035-11-15 08:23:44 +0000 UTC (now=2025-11-17 09:33:53.802156578 +0000 UTC))"
2025-11-17T09:33:53.802227770Z I1117 09:33:53.802218       1 tlsconfig.go:178] "Loaded client CA" index=1 certName="client-ca::kube-system::extension-apiserver-authentication::client-ca-file,client-ca::kube-system::extension-apiserver-authentication::requestheader-client-ca-file" certDetail="\"kubelet-signer\" [] issuer=\"<self>\" (2025-11-17 09:01:29 +0000 UTC to 2025-11-18 09:01:29 +0000 UTC (now=2025-11-17 09:33:53.802205521 +0000 UTC))"
2025-11-17T09:33:53.802246887Z I1117 09:33:53.802236       1 tlsconfig.go:178] "Loaded client CA" index=2 certName="client-ca::kube-system::extension-apiserver-authentication::client-ca-file,client-ca::kube-system::extension-apiserver-authentication::requestheader-client-ca-file" certDetail="\"kube-control-plane-signer\" [] issuer=\"<self>\" (2025-11-17 09:01:29 +0000 UTC to 2026-11-17 09:01:29 +0000 UTC (now=2025-11-17 09:33:53.802225433 +0000 UTC))"
2025-11-17T09:33:53.802270553Z I1117 09:33:53.802255       1 tlsconfig.go:178] "Loaded client CA" index=3 certName="client-ca::kube-system::extension-apiserver-authentication::client-ca-file,client-ca::kube-system::extension-apiserver-authentication::requestheader-client-ca-file" certDetail="\"kube-apiserver-to-kubelet-signer\" [] issuer=\"<self>\" (2025-11-17 09:01:29 +0000 UTC to 2026-11-17 09:01:29 +0000 UTC (now=2025-11-17 09:33:53.802245388 +0000 UTC))"
2025-11-17T09:33:53.802291251Z I1117 09:33:53.802281       1 tlsconfig.go:178] "Loaded client CA" index=4 certName="client-ca::kube-system::extension-apiserver-authentication::client-ca-file,client-ca::kube-system::extension-apiserver-authentication::requestheader-client-ca-file" certDetail="\"kubelet-bootstrap-kubeconfig-signer\" [] issuer=\"<self>\" (2025-11-17 09:01:27 +0000 UTC to 2035-11-15 09:01:27 +0000 UTC (now=2025-11-17 09:33:53.802270139 +0000 UTC))"
2025-11-17T09:33:53.802308323Z I1117 09:33:53.802298       1 tlsconfig.go:178] "Loaded client CA" index=5 certName="client-ca::kube-system::extension-apiserver-authentication::client-ca-file,client-ca::kube-system::extension-apiserver-authentication::requestheader-client-ca-file" certDetail="\"kube-csr-signer_@1763371225\" [] issuer=\"kubelet-signer\" (2025-11-17 09:20:25 +0000 UTC to 2025-11-18 09:01:29 +0000 UTC (now=2025-11-17 09:33:53.802289096 +0000 UTC))"
2025-11-17T09:33:53.802328708Z I1117 09:33:53.802318       1 tlsconfig.go:178] "Loaded client CA" index=6 certName="client-ca::kube-system::extension-apiserver-authentication::client-ca-file,client-ca::kube-system::extension-apiserver-authentication::requestheader-client-ca-file" certDetail="\"openshift-kube-apiserver-operator_node-system-admin-signer@1763371229\" [] issuer=\"<self>\" (2025-11-17 09:20:28 +0000 UTC to 2026-11-17 09:20:29 +0000 UTC (now=2025-11-17 09:33:53.802306183 +0000 UTC))"
2025-11-17T09:33:53.802733999Z I1117 09:33:53.802718       1 tlsconfig.go:200] "Loaded serving cert" certName="serving-cert::/etc/kubernetes/static-pod-resources/secrets/serving-cert/tls.crt::/etc/kubernetes/static-pod-resources/secrets/serving-cert/tls.key" certDetail="\"scheduler.openshift-kube-scheduler.svc\" [serving] validServingFor=[scheduler.openshift-kube-scheduler.svc,scheduler.openshift-kube-scheduler.svc.cluster.local] issuer=\"openshift-service-serving-signer@1763371220\" (2025-11-17 09:20:36 +0000 UTC to 2027-11-17 09:20:37 +0000 UTC (now=2025-11-17 09:33:53.802700763 +0000 UTC))"
2025-11-17T09:33:53.803144512Z I1117 09:33:53.803128       1 named_certificates.go:53] "Loaded SNI cert" index=0 certName="self-signed loopback" certDetail="\"apiserver-loopback-client@1763372033\" [serving] validServingFor=[apiserver-loopback-client] issuer=\"apiserver-loopback-client-ca@1763372033\" (2025-11-17 08:33:53 +0000 UTC to 2026-11-17 08:33:53 +0000 UTC (now=2025-11-17 09:33:53.803113644 +0000 UTC))"
2025-11-17T09:33:53.803252652Z I1117 09:33:53.803235       1 leaderelection.go:245] attempting to acquire leader lease openshift-kube-scheduler/kube-scheduler...
2025-11-17T09:33:53.803276077Z I1117 09:33:53.803256       1 tlsconfig.go:178] "Loaded client CA" index=0 certName="client-ca::kube-system::extension-apiserver-authentication::client-ca-file,client-ca::kube-system::extension-apiserver-authentication::requestheader-client-ca-file" certDetail="\"admin-kubeconfig-signer\" [] issuer=\"<self>\" (2025-11-17 08:23:44 +0000 UTC to 2035-11-15 08:23:44 +0000 UTC (now=2025-11-17 09:33:53.803242858 +0000 UTC))"
2025-11-17T09:33:53.803294976Z I1117 09:33:53.803285       1 tlsconfig.go:178] "Loaded client CA" index=1 certName="client-ca::kube-system::extension-apiserver-authentication::client-ca-file,client-ca::kube-system::extension-apiserver-authentication::requestheader-client-ca-file" certDetail="\"kubelet-signer\" [] issuer=\"<self>\" (2025-11-17 09:01:29 +0000 UTC to 2025-11-18 09:01:29 +0000 UTC (now=2025-11-17 09:33:53.803274525 +0000 UTC))"
2025-11-17T09:33:53.803313308Z I1117 09:33:53.803303       1 tlsconfig.go:178] "Loaded client CA" index=2 certName="client-ca::kube-system::extension-apiserver-authentication::client-ca-file,client-ca::kube-system::extension-apiserver-authentication::requestheader-client-ca-file" certDetail="\"kube-control-plane-signer\" [] issuer=\"<self>\" (2025-11-17 09:01:29 +0000 UTC to 2026-11-17 09:01:29 +0000 UTC (now=2025-11-17 09:33:53.803293019 +0000 UTC))"
2025-11-17T09:33:53.803331950Z I1117 09:33:53.803322       1 tlsconfig.go:178] "Loaded client CA" index=3 certName="client-ca::kube-system::extension-apiserver-authentication::client-ca-file,client-ca::kube-system::extension-apiserver-authentication::requestheader-client-ca-file" certDetail="\"kube-apiserver-to-kubelet-signer\" [] issuer=\"<self>\" (2025-11-17 09:01:29 +0000 UTC to 2026-11-17 09:01:29 +0000 UTC (now=2025-11-17 09:33:53.803311398 +0000 UTC))"
2025-11-17T09:33:53.803356843Z I1117 09:33:53.803344       1 tlsconfig.go:178] "Loaded client CA" index=4 certName="client-ca::kube-system::extension-apiserver-authentication::client-ca-file,client-ca::kube-system::extension-apiserver-authentication::requestheader-client-ca-file" certDetail="\"kubelet-bootstrap-kubeconfig-signer\" [] issuer=\"<self>\" (2025-11-17 09:01:27 +0000 UTC to 2035-11-15 09:01:27 +0000 UTC (now=2025-11-17 09:33:53.803329644 +0000 UTC))"
2025-11-17T09:33:53.803379380Z I1117 09:33:53.803369       1 tlsconfig.go:178] "Loaded client CA" index=5 certName="client-ca::kube-system::extension-apiserver-authentication::client-ca-file,client-ca::kube-system::extension-apiserver-authentication::requestheader-client-ca-file" certDetail="\"kube-csr-signer_@1763371225\" [] issuer=\"kubelet-signer\" (2025-11-17 09:20:25 +0000 UTC to 2025-11-18 09:01:29 +0000 UTC (now=2025-11-17 09:33:53.803356222 +0000 UTC))"
2025-11-17T09:33:53.803398271Z I1117 09:33:53.803388       1 tlsconfig.go:178] "Loaded client CA" index=6 certName="client-ca::kube-system::extension-apiserver-authentication::client-ca-file,client-ca::kube-system::extension-apiserver-authentication::requestheader-client-ca-file" certDetail="\"openshift-kube-apiserver-operator_node-system-admin-signer@1763371229\" [] issuer=\"<self>\" (2025-11-17 09:20:28 +0000 UTC to 2026-11-17 09:20:29 +0000 UTC (now=2025-11-17 09:33:53.80337676 +0000 UTC))"
2025-11-17T09:33:53.803442120Z I1117 09:33:53.803422       1 tlsconfig.go:178] "Loaded client CA" index=7 certName="client-ca::kube-system::extension-apiserver-authentication::client-ca-file,client-ca::kube-system::extension-apiserver-authentication::requestheader-client-ca-file" certDetail="\"aggregator-signer\" [] issuer=\"<self>\" (2025-11-17 09:01:28 +0000 UTC to 2025-11-18 09:01:28 +0000 UTC (now=2025-11-17 09:33:53.803396052 +0000 UTC))"
2025-11-17T09:33:53.803838185Z I1117 09:33:53.803821       1 tlsconfig.go:200] "Loaded serving cert" certName="serving-cert::/etc/kubernetes/static-pod-resources/secrets/serving-cert/tls.crt::/etc/kubernetes/static-pod-resources/secrets/serving-cert/tls.key" certDetail="\"scheduler.openshift-kube-scheduler.svc\" [serving] validServingFor=[scheduler.openshift-kube-scheduler.svc,scheduler.openshift-kube-scheduler.svc.cluster.local] issuer=\"openshift-service-serving-signer@1763371220\" (2025-11-17 09:20:36 +0000 UTC to 2027-11-17 09:20:37 +0000 UTC (now=2025-11-17 09:33:53.803805206 +0000 UTC))"
2025-11-17T09:33:53.804244715Z I1117 09:33:53.804216       1 named_certificates.go:53] "Loaded SNI cert" index=0 certName="self-signed loopback" certDetail="\"apiserver-loopback-client@1763372033\" [serving] validServingFor=[apiserver-loopback-client] issuer=\"apiserver-loopback-client-ca@1763372033\" (2025-11-17 08:33:53 +0000 UTC to 2026-11-17 08:33:53 +0000 UTC (now=2025-11-17 09:33:53.80419866 +0000 UTC))"
2025-11-17T09:36:56.503680888Z I1117 09:36:56.503620       1 leaderelection.go:255] successfully acquired lease openshift-kube-scheduler/kube-scheduler
2025-11-17T09:36:56.505276558Z I1117 09:36:56.505248       1 schedule_one.go:889] "Unable to schedule pod; no fit; waiting" pod="openshift-controller-manager/controller-manager-89cf55877-hlqxw" err="0/5 nodes are available: 2 node(s) didn't match pod anti-affinity rules, 3 node(s) had untolerated taint {node.kubernetes.io/not-ready: }. preemption: 0/5 nodes are available: 2 node(s) didn't match pod anti-affinity rules, 3 Preemption is not helpful for scheduling.."
2025-11-17T09:36:56.510988490Z I1117 09:36:56.510954       1 schedule_one.go:252] "Successfully bound pod to node" pod="openshift-cluster-node-tuning-operator/tuned-p2xqq" node="XXXXXX0" evaluatedNodes=1 feasibleNodes=1
2025-11-17T09:36:56.514331199Z I1117 09:36:56.514257       1 schedule_one.go:252] "Successfully bound pod to node" pod="openshift-cluster-node-tuning-operator/tuned-l8dpn" node="XXXXXX1" evaluatedNodes=1 feasibleNodes=1
2025-11-17T09:36:56.517095985Z I1117 09:36:56.517048       1 schedule_one.go:252] "Successfully bound pod to node" pod="openshift-cluster-node-tuning-operator/tuned-87llx" node="XXXXXX0" evaluatedNodes=1 feasibleNodes=1
2025-11-17T09:36:56.526775687Z I1117 09:36:56.525882       1 schedule_one.go:889] "Unable to schedule pod; no fit; waiting" pod="openshift-oauth-apiserver/apiserver-795447c5f-c8cv2" err="0/5 nodes are available: 2 node(s) didn't match pod anti-affinity rules, 3 node(s) had untolerated taint {node.kubernetes.io/not-ready: }. preemption: 0/5 nodes are available: 2 node(s) didn't match pod anti-affinity rules, 3 Preemption is not helpful for scheduling.."
2025-11-17T09:36:56.530003938Z I1117 09:36:56.529910       1 schedule_one.go:252] "Successfully bound pod to node" pod="openshift-multus/multus-additional-cni-plugins-b5c7h" node="XXXXXX0" evaluatedNodes=1 feasibleNodes=1
2025-11-17T09:36:56.530047213Z I1117 09:36:56.530031       1 schedule_one.go:252] "Successfully bound pod to node" pod="openshift-machine-config-operator/machine-config-daemon-wj2c4" node="XXXXXX1" evaluatedNodes=1 feasibleNodes=1
2025-11-17T09:36:56.533141467Z I1117 09:36:56.533076       1 schedule_one.go:252] "Successfully bound pod to node" pod="openshift-multus/network-metrics-daemon-xq955" node="XXXXXX1" evaluatedNodes=1 feasibleNodes=1
2025-11-17T09:36:56.543794305Z I1117 09:36:56.543134       1 schedule_one.go:252] "Successfully bound pod to node" pod="openshift-machine-config-operator/machine-config-daemon-888sf" node="XXXXXX0" evaluatedNodes=1 feasibleNodes=1
2025-11-17T09:36:56.543794305Z I1117 09:36:56.543458       1 schedule_one.go:252] "Successfully bound pod to node" pod="openshift-multus/network-metrics-daemon-kzf9c" node="XXXXXX0" evaluatedNodes=1 feasibleNodes=1
2025-11-17T09:36:56.543794305Z I1117 09:36:56.543662       1 schedule_one.go:252] "Successfully bound pod to node" pod="openshift-network-node-identity/network-node-identity-qzm58" node="XXXXXX0" evaluatedNodes=1 feasibleNodes=1
2025-11-17T09:36:56.544551995Z I1117 09:36:56.543951       1 schedule_one.go:252] "Successfully bound pod to node" pod="openshift-multus/multus-xjm8q" node="XXXXXX1" evaluatedNodes=1 feasibleNodes=1
2025-11-17T09:36:56.544551995Z I1117 09:36:56.544160       1 schedule_one.go:252] "Successfully bound pod to node" pod="openshift-dns/node-resolver-q4ctm" node="XXXXXX0" evaluatedNodes=1 feasibleNodes=1
2025-11-17T09:36:56.544551995Z I1117 09:36:56.544290       1 schedule_one.go:252] "Successfully bound pod to node" pod="openshift-dns/node-resolver-t668g" node="XXXXXX0" evaluatedNodes=1 feasibleNodes=1
2025-11-17T09:36:56.546514160Z I1117 09:36:56.545978       1 schedule_one.go:252] "Successfully bound pod to node" pod="openshift-dns/node-resolver-w5qs9" node="XXXXXX1" evaluatedNodes=1 feasibleNodes=1
2025-11-17T09:36:56.546514160Z I1117 09:36:56.546157       1 schedule_one.go:252] "Successfully bound pod to node" pod="openshift-multus/multus-86hlp" node="XXXXXX0" evaluatedNodes=1 feasibleNodes=1
2025-11-17T09:36:56.546514160Z I1117 09:36:56.546279       1 schedule_one.go:252] "Successfully bound pod to node" pod="openshift-multus/multus-85xch" node="XXXXXX0" evaluatedNodes=1 feasibleNodes=1
2025-11-17T09:36:56.546514160Z I1117 09:36:56.546387       1 schedule_one.go:252] "Successfully bound pod to node" pod="openshift-multus/network-metrics-daemon-l6kwt" node="XXXXXX0" evaluatedNodes=1 feasibleNodes=1
2025-11-17T09:36:56.549782632Z I1117 09:36:56.548972       1 schedule_one.go:889] "Unable to schedule pod; no fit; waiting" pod="openshift-route-controller-manager/route-controller-manager-7678bd4c5f-f8xlv" err="0/5 nodes are available: 2 node(s) didn't match pod anti-affinity rules, 3 node(s) had untolerated taint {node.kubernetes.io/not-ready: }. preemption: 0/5 nodes are available: 2 node(s) didn't match pod anti-affinity rules, 3 Preemption is not helpful for scheduling.."
2025-11-17T09:36:56.553753945Z I1117 09:36:56.552746       1 schedule_one.go:252] "Successfully bound pod to node" pod="openshift-machine-config-operator/machine-config-daemon-b6k8l" node="XXXXXX0" evaluatedNodes=1 feasibleNodes=1
2025-11-17T09:36:56.553753945Z I1117 09:36:56.553153       1 schedule_one.go:252] "Successfully bound pod to node" pod="openshift-multus/multus-additional-cni-plugins-p9csb" node="XXXXXX0" evaluatedNodes=1 feasibleNodes=1
2025-11-17T09:36:56.553753945Z I1117 09:36:56.553341       1 schedule_one.go:252] "Successfully bound pod to node" pod="openshift-multus/multus-additional-cni-plugins-h7p55" node="XXXXXX1" evaluatedNodes=1 feasibleNodes=1
2025-11-17T09:36:56.563064239Z I1117 09:36:56.561083       1 schedule_one.go:252] "Successfully bound pod to node" pod="openshift-ovn-kubernetes/ovnkube-node-dwqcv" node="XXXXXX0" evaluatedNodes=1 feasibleNodes=1
2025-11-17T09:36:56.568798967Z I1117 09:36:56.567423       1 schedule_one.go:889] "Unable to schedule pod; no fit; waiting" pod="openshift-ingress/router-default-668949fb46-52qxp" err="0/5 nodes are available: 2 node(s) had untolerated taint {node.kubernetes.io/not-ready: }, 3 node(s) had untolerated taint {node-role.kubernetes.io/XXXXXX: }. preemption: 0/5 nodes are available: 5 Preemption is not helpful for scheduling.."
2025-11-17T09:36:56.569508133Z I1117 09:36:56.569184       1 schedule_one.go:252] "Successfully bound pod to node" pod="openshift-ovn-kubernetes/ovnkube-node-r5bjq" node="XXXXXX1" evaluatedNodes=1 feasibleNodes=1
2025-11-17T09:36:56.584038456Z I1117 09:36:56.583903       1 schedule_one.go:252] "Successfully bound pod to node" pod="openshift-ovn-kubernetes/ovnkube-node-jj2tm" node="XXXXXX0" evaluatedNodes=1 feasibleNodes=1
2025-11-17T09:36:56.584038456Z I1117 09:36:56.583920       1 schedule_one.go:252] "Successfully bound pod to node" pod="openshift-image-registry/node-ca-4prkz" node="XXXXXX1" evaluatedNodes=1 feasibleNodes=1
2025-11-17T09:36:56.590984825Z I1117 09:36:56.589797       1 schedule_one.go:252] "Successfully bound pod to node" pod="openshift-image-registry/node-ca-mwhjw" node="XXXXXX0" evaluatedNodes=1 feasibleNodes=1
2025-11-17T09:36:56.590984825Z I1117 09:36:56.590041       1 schedule_one.go:252] "Successfully bound pod to node" pod="openshift-image-registry/node-ca-9n78h" node="XXXXXX0" evaluatedNodes=1 feasibleNodes=1
2025-11-17T09:36:56.604164394Z I1117 09:36:56.603930       1 schedule_one.go:889] "Unable to schedule pod; no fit; waiting" pod="openshift-ingress/router-default-668949fb46-d6qkr" err="0/5 nodes are available: 2 node(s) had untolerated taint {node.kubernetes.io/not-ready: }, 3 node(s) had untolerated taint {node-role.kubernetes.io/XXXXXX: }. preemption: 0/5 nodes are available: 5 Preemption is not helpful for scheduling.."
2025-11-17T09:36:56.619722366Z I1117 09:36:56.619063       1 schedule_one.go:889] "Unable to schedule pod; no fit; waiting" pod="openshift-monitoring/prometheus-operator-admission-webhook-686c664ffb-qdprf" err="0/5 nodes are available: 2 node(s) had untolerated taint {node.kubernetes.io/not-ready: }, 3 node(s) had untolerated taint {node-role.kubernetes.io/XXXXXX: }. preemption: 0/5 nodes are available: 5 Preemption is not helpful for scheduling.."
2025-11-17T09:36:56.628797256Z I1117 09:36:56.627524       1 schedule_one.go:252] "Successfully bound pod to node" pod="openshift-marketplace/community-operators-46r88" node="XXXXXX1" evaluatedNodes=5 feasibleNodes=2
2025-11-17T09:36:56.628797256Z I1117 09:36:56.627734       1 schedule_one.go:252] "Successfully bound pod to node" pod="openshift-marketplace/redhat-operators-4c56h" node="XXXXXX1" evaluatedNodes=5 feasibleNodes=2
2025-11-17T09:36:56.635857025Z I1117 09:36:56.634900       1 schedule_one.go:252] "Successfully bound pod to node" pod="openshift-marketplace/certified-operators-7hvs9" node="XXXXXX1" evaluatedNodes=5 feasibleNodes=2
2025-11-17T09:36:56.644544888Z I1117 09:36:56.644479       1 schedule_one.go:252] "Successfully bound pod to node" pod="openshift-marketplace/redhat-marketplace-x56kr" node="XXXXXX1" evaluatedNodes=5 feasibleNodes=2
2025-11-17T09:36:56.644885607Z I1117 09:36:56.644853       1 schedule_one.go:889] "Unable to schedule pod; no fit; waiting" pod="openshift-monitoring/prometheus-operator-admission-webhook-686c664ffb-xlz8g" err="0/5 nodes are available: 2 node(s) had untolerated taint {node.kubernetes.io/not-ready: }, 3 node(s) had untolerated taint {node-role.kubernetes.io/XXXXXX: }. preemption: 0/5 nodes are available: 5 Preemption is not helpful for scheduling.."
2025-11-17T09:36:56.664655824Z I1117 09:36:56.664616       1 schedule_one.go:889] "Unable to schedule pod; no fit; waiting" pod="openshift-network-diagnostics/network-check-source-b56b967f4-6jv22" err="0/5 nodes are available: 2 node(s) had untolerated taint {node.kubernetes.io/not-ready: }, 3 node(s) had untolerated taint {node-role.kubernetes.io/XXXXXX: }. preemption: 0/5 nodes are available: 5 Preemption is not helpful for scheduling.."
2025-11-17T09:36:56.674881107Z I1117 09:36:56.674609       1 schedule_one.go:889] "Unable to schedule pod; no fit; waiting" pod="openshift-operator-lifecycle-manager/collect-profiles-29389530-f4dqp" err="0/5 nodes are available: 2 node(s) had untolerated taint {node.kubernetes.io/not-ready: }, 3 node(s) had untolerated taint {node-role.kubernetes.io/XXXXXX: }. preemption: 0/5 nodes are available: 5 Preemption is not helpful for scheduling.."
2025-11-17T09:36:56.688792566Z I1117 09:36:56.686789       1 schedule_one.go:252] "Successfully bound pod to node" pod="openshift-network-diagnostics/network-check-target-wcbr5" node="XXXXXX0" evaluatedNodes=1 feasibleNodes=1
2025-11-17T09:36:56.688792566Z I1117 09:36:56.687110       1 schedule_one.go:252] "Successfully bound pod to node" pod="openshift-multus/multus-admission-controller-7f5d5667bf-lw7qh" node="XXXXXX1" evaluatedNodes=5 feasibleNodes=2
2025-11-17T09:36:56.699709970Z I1117 09:36:56.698934       1 schedule_one.go:252] "Successfully bound pod to node" pod="openshift-network-diagnostics/network-check-target-mx9tb" node="XXXXXX0" evaluatedNodes=1 feasibleNodes=1
2025-11-17T09:36:56.699709970Z I1117 09:36:56.698978       1 schedule_one.go:252] "Successfully bound pod to node" pod="openshift-network-diagnostics/network-check-target-fl5jm" node="XXXXXX1" evaluatedNodes=1 feasibleNodes=1
2025-11-17T09:36:58.506914315Z I1117 09:36:58.506871       1 schedule_one.go:889] "Unable to schedule pod; no fit; waiting" pod="openshift-route-controller-manager/route-controller-manager-7678bd4c5f-f8xlv" err="0/5 nodes are available: 2 node(s) didn't match pod anti-affinity rules, 3 node(s) had untolerated taint {node.kubernetes.io/not-ready: }. preemption: 0/5 nodes are available: 2 node(s) didn't match pod anti-affinity rules, 3 Preemption is not helpful for scheduling.."
2025-11-17T09:36:58.507367731Z I1117 09:36:58.507261       1 schedule_one.go:889] "Unable to schedule pod; no fit; waiting" pod="openshift-monitoring/prometheus-operator-admission-webhook-686c664ffb-xlz8g" err="0/5 nodes are available: 2 node(s) had untolerated taint {node.kubernetes.io/not-ready: }, 3 node(s) had untolerated taint {node-role.kubernetes.io/XXXXXX: }. preemption: 0/5 nodes are available: 5 Preemption is not helpful for scheduling.."
2025-11-17T09:37:04.943720463Z I1117 09:37:04.942673       1 schedule_one.go:889] "Unable to schedule pod; no fit; waiting" pod="openshift-apiserver/apiserver-c96548dc-qrqnf" err="0/5 nodes are available: 2 node(s) didn't match pod anti-affinity rules, 3 node(s) had untolerated taint {node.kubernetes.io/not-ready: }. preemption: 0/5 nodes are available: 2 node(s) didn't match pod anti-affinity rules, 3 Preemption is not helpful for scheduling.."
2025-11-17T09:37:09.966156574Z I1117 09:37:09.966113       1 schedule_one.go:252] "Successfully bound pod to node" pod="openshift-multus/multus-admission-controller-7f5d5667bf-rkv4m" node="XXXXXX2" evaluatedNodes=5 feasibleNodes=2
2025-11-17T09:37:10.306115248Z I1117 09:37:10.306077       1 schedule_one.go:889] "Unable to schedule pod; no fit; waiting" pod="openshift-controller-manager/controller-manager-89cf55877-hlqxw" err="0/5 nodes are available: 2 node(s) didn't match pod anti-affinity rules, 3 node(s) had untolerated taint {node.kubernetes.io/not-ready: }. preemption: 0/5 nodes are available: 2 node(s) didn't match pod anti-affinity rules, 3 Preemption is not helpful for scheduling.."
2025-11-17T09:37:10.308810963Z I1117 09:37:10.306947       1 schedule_one.go:889] "Unable to schedule pod; no fit; waiting" pod="openshift-oauth-apiserver/apiserver-795447c5f-c8cv2" err="0/5 nodes are available: 2 node(s) didn't match pod anti-affinity rules, 3 node(s) had untolerated taint {node.kubernetes.io/not-ready: }. preemption: 0/5 nodes are available: 2 node(s) didn't match pod anti-affinity rules, 3 Preemption is not helpful for scheduling.."
2025-11-17T09:37:10.309574242Z I1117 09:37:10.309537       1 schedule_one.go:889] "Unable to schedule pod; no fit; waiting" pod="openshift-route-controller-manager/route-controller-manager-7678bd4c5f-f8xlv" err="0/5 nodes are available: 2 node(s) didn't match pod anti-affinity rules, 3 node(s) had untolerated taint {node.kubernetes.io/not-ready: }. preemption: 0/5 nodes are available: 2 node(s) didn't match pod anti-affinity rules, 3 Preemption is not helpful for scheduling.."
2025-11-17T09:37:10.310117475Z I1117 09:37:10.310093       1 schedule_one.go:889] "Unable to schedule pod; no fit; waiting" pod="openshift-apiserver/apiserver-c96548dc-qrqnf" err="0/5 nodes are available: 2 node(s) didn't match pod anti-affinity rules, 3 node(s) had untolerated taint {node.kubernetes.io/not-ready: }. preemption: 0/5 nodes are available: 2 node(s) didn't match pod anti-affinity rules, 3 Preemption is not helpful for scheduling.."
2025-11-17T09:37:12.517613013Z I1117 09:37:12.517537       1 schedule_one.go:889] "Unable to schedule pod; no fit; waiting" pod="openshift-controller-manager/controller-manager-89cf55877-hlqxw" err="0/5 nodes are available: 2 node(s) didn't match pod anti-affinity rules, 3 node(s) had untolerated taint {node.kubernetes.io/not-ready: }. preemption: 0/5 nodes are available: 2 node(s) didn't match pod anti-affinity rules, 3 Preemption is not helpful for scheduling.."
2025-11-17T09:37:12.518174111Z I1117 09:37:12.518137       1 schedule_one.go:889] "Unable to schedule pod; no fit; waiting" pod="openshift-oauth-apiserver/apiserver-795447c5f-c8cv2" err="0/5 nodes are available: 2 node(s) didn't match pod anti-affinity rules, 3 node(s) had untolerated taint {node.kubernetes.io/not-ready: }. preemption: 0/5 nodes are available: 2 node(s) didn't match pod anti-affinity rules, 3 Preemption is not helpful for scheduling.."
2025-11-17T09:37:12.518627129Z I1117 09:37:12.518588       1 schedule_one.go:889] "Unable to schedule pod; no fit; waiting" pod="openshift-apiserver/apiserver-c96548dc-qrqnf" err="0/5 nodes are available: 2 node(s) didn't match pod anti-affinity rules, 3 node(s) had untolerated taint {node.kubernetes.io/not-ready: }. preemption: 0/5 nodes are available: 2 node(s) didn't match pod anti-affinity rules, 3 Preemption is not helpful for scheduling.."
2025-11-17T09:37:14.519207174Z I1117 09:37:14.519134       1 schedule_one.go:889] "Unable to schedule pod; no fit; waiting" pod="openshift-route-controller-manager/route-controller-manager-7678bd4c5f-f8xlv" err="0/5 nodes are available: 2 node(s) didn't match pod anti-affinity rules, 3 node(s) had untolerated taint {node.kubernetes.io/not-ready: }. preemption: 0/5 nodes are available: 2 node(s) didn't match pod anti-affinity rules, 3 Preemption is not helpful for scheduling.."
2025-11-17T09:37:39.057911877Z I1117 09:37:39.057857       1 schedule_one.go:889] "Unable to schedule pod; no fit; waiting" pod="openshift-controller-manager/controller-manager-89cf55877-hlqxw" err="0/5 nodes are available: 2 node(s) didn't match pod anti-affinity rules, 3 node(s) had untolerated taint {node.kubernetes.io/not-ready: }. preemption: 0/5 nodes are available: 2 node(s) didn't match pod anti-affinity rules, 3 Preemption is not helpful for scheduling.."
2025-11-17T09:37:39.058703705Z I1117 09:37:39.058664       1 schedule_one.go:889] "Unable to schedule pod; no fit; waiting" pod="openshift-oauth-apiserver/apiserver-795447c5f-c8cv2" err="0/5 nodes are available: 2 node(s) didn't match pod anti-affinity rules, 3 node(s) had untolerated taint {node.kubernetes.io/not-ready: }. preemption: 0/5 nodes are available: 2 node(s) didn't match pod anti-affinity rules, 3 Preemption is not helpful for scheduling.."
2025-11-17T09:37:39.059289262Z I1117 09:37:39.059195       1 schedule_one.go:889] "Unable to schedule pod; no fit; waiting" pod="openshift-apiserver/apiserver-c96548dc-qrqnf" err="0/5 nodes are available: 2 node(s) didn't match pod anti-affinity rules, 3 node(s) had untolerated taint {node.kubernetes.io/not-ready: }. preemption: 0/5 nodes are available: 2 node(s) didn't match pod anti-affinity rules, 3 Preemption is not helpful for scheduling.."
2025-11-17T09:37:39.060122183Z I1117 09:37:39.059789       1 schedule_one.go:889] "Unable to schedule pod; no fit; waiting" pod="openshift-route-controller-manager/route-controller-manager-7678bd4c5f-f8xlv" err="0/5 nodes are available: 2 node(s) didn't match pod anti-affinity rules, 3 node(s) had untolerated taint {node.kubernetes.io/not-ready: }. preemption: 0/5 nodes are available: 2 node(s) didn't match pod anti-affinity rules, 3 Preemption is not helpful for scheduling.."
2025-11-17T09:37:53.952133075Z I1117 09:37:53.952046       1 schedule_one.go:889] "Unable to schedule pod; no fit; waiting" pod="openshift-controller-manager/controller-manager-89cf55877-hlqxw" err="0/5 nodes are available: 2 node(s) didn't match pod anti-affinity rules, 3 node(s) had untolerated taint {node.kubernetes.io/not-ready: }. preemption: 0/5 nodes are available: 2 node(s) didn't match pod anti-affinity rules, 3 Preemption is not helpful for scheduling.."
2025-11-17T09:37:53.952880353Z I1117 09:37:53.952854       1 schedule_one.go:889] "Unable to schedule pod; no fit; waiting" pod="openshift-oauth-apiserver/apiserver-795447c5f-c8cv2" err="0/5 nodes are available: 2 node(s) didn't match pod anti-affinity rules, 3 node(s) had untolerated taint {node.kubernetes.io/not-ready: }. preemption: 0/5 nodes are available: 2 node(s) didn't match pod anti-affinity rules, 3 Preemption is not helpful for scheduling.."
2025-11-17T09:37:53.953544524Z I1117 09:37:53.953512       1 schedule_one.go:889] "Unable to schedule pod; no fit; waiting" pod="openshift-apiserver/apiserver-c96548dc-qrqnf" err="0/5 nodes are available: 2 node(s) didn't match pod anti-affinity rules, 3 node(s) had untolerated taint {node.kubernetes.io/not-ready: }. preemption: 0/5 nodes are available: 2 node(s) didn't match pod anti-affinity rules, 3 Preemption is not helpful for scheduling.."
2025-11-17T09:37:53.954078393Z I1117 09:37:53.954053       1 schedule_one.go:889] "Unable to schedule pod; no fit; waiting" pod="openshift-route-controller-manager/route-controller-manager-7678bd4c5f-f8xlv" err="0/5 nodes are available: 2 node(s) didn't match pod anti-affinity rules, 3 node(s) had untolerated taint {node.kubernetes.io/not-ready: }. preemption: 0/5 nodes are available: 2 node(s) didn't match pod anti-affinity rules, 3 Preemption is not helpful for scheduling.."
2025-11-17T09:38:04.545521441Z I1117 09:38:04.545368       1 schedule_one.go:889] "Unable to schedule pod; no fit; waiting" pod="openshift-controller-manager/controller-manager-89cf55877-hlqxw" err="0/5 nodes are available: 2 node(s) didn't match pod anti-affinity rules, 3 node(s) had untolerated taint {node.kubernetes.io/not-ready: }. preemption: 0/5 nodes are available: 2 node(s) didn't match pod anti-affinity rules, 3 Preemption is not helpful for scheduling.."
2025-11-17T09:38:04.545984617Z I1117 09:38:04.545942       1 schedule_one.go:889] "Unable to schedule pod; no fit; waiting" pod="openshift-oauth-apiserver/apiserver-795447c5f-c8cv2" err="0/5 nodes are available: 2 node(s) didn't match pod anti-affinity rules, 3 node(s) had untolerated taint {node.kubernetes.io/not-ready: }. preemption: 0/5 nodes are available: 2 node(s) didn't match pod anti-affinity rules, 3 Preemption is not helpful for scheduling.."
2025-11-17T09:38:04.546402638Z I1117 09:38:04.546382       1 schedule_one.go:889] "Unable to schedule pod; no fit; waiting" pod="openshift-apiserver/apiserver-c96548dc-qrqnf" err="0/5 nodes are available: 2 node(s) didn't match pod anti-affinity rules, 3 node(s) had untolerated taint {node.kubernetes.io/not-ready: }. preemption: 0/5 nodes are available: 2 node(s) didn't match pod anti-affinity rules, 3 Preemption is not helpful for scheduling.."
2025-11-17T09:38:04.546787619Z I1117 09:38:04.546764       1 schedule_one.go:889] "Unable to schedule pod; no fit; waiting" pod="openshift-route-controller-manager/route-controller-manager-7678bd4c5f-f8xlv" err="0/5 nodes are available: 2 node(s) didn't match pod anti-affinity rules, 3 node(s) had untolerated taint {node.kubernetes.io/not-ready: }. preemption: 0/5 nodes are available: 2 node(s) didn't match pod anti-affinity rules, 3 Preemption is not helpful for scheduling.."
2025-11-17T09:38:21.812175242Z I1117 09:38:21.812129       1 schedule_one.go:252] "Successfully bound pod to node" pod="openshift-route-controller-manager/route-controller-manager-7678bd4c5f-f8xlv" node="XXXXXX0" evaluatedNodes=5 feasibleNodes=1
2025-11-17T09:38:21.847554737Z I1117 09:38:21.847513       1 schedule_one.go:252] "Successfully bound pod to node" pod="openshift-controller-manager/controller-manager-89cf55877-hlqxw" node="XXXXXX0" evaluatedNodes=5 feasibleNodes=1
2025-11-17T09:38:21.868672108Z I1117 09:38:21.868621       1 schedule_one.go:252] "Successfully bound pod to node" pod="openshift-oauth-apiserver/apiserver-795447c5f-c8cv2" node="XXXXXX0" evaluatedNodes=5 feasibleNodes=1
2025-11-17T09:38:21.911954165Z I1117 09:38:21.911861       1 schedule_one.go:252] "Successfully bound pod to node" pod="openshift-apiserver/apiserver-c96548dc-qrqnf" node="XXXXXX0" evaluatedNodes=5 feasibleNodes=1
2025-11-17T09:38:22.724393833Z I1117 09:38:22.719215       1 schedule_one.go:252] "Successfully bound pod to node" pod="openshift-machine-config-operator/machine-config-server-r5hqw" node="XXXXXX0" evaluatedNodes=1 feasibleNodes=1
2025-11-17T09:38:22.724393833Z I1117 09:38:22.719479       1 schedule_one.go:252] "Successfully bound pod to node" pod="openshift-machine-api/ironic-proxy-7dp6w" node="XXXXXX0" evaluatedNodes=1 feasibleNodes=1
2025-11-17T09:38:22.744787000Z I1117 09:38:22.744730       1 schedule_one.go:889] "Unable to schedule pod; no fit; waiting" pod="openshift-ingress/router-default-668949fb46-d6qkr" err="0/5 nodes are available: 1 node(s) didn't have free ports for the requested pod ports, 1 node(s) had untolerated taint {node.kubernetes.io/not-ready: }, 3 node(s) had untolerated taint {node-role.kubernetes.io/XXXXXX: }. preemption: 0/5 nodes are available: 1 node(s) didn't have free ports for the requested pod ports, 4 Preemption is not helpful for scheduling.."
2025-11-17T09:38:22.864147424Z I1117 09:38:22.864083       1 schedule_one.go:889] "Unable to schedule pod; no fit; waiting" pod="openshift-monitoring/prometheus-operator-admission-webhook-686c664ffb-xlz8g" err="0/5 nodes are available: 1 node(s) didn't match pod anti-affinity rules, 1 node(s) had untolerated taint {node.kubernetes.io/not-ready: }, 3 node(s) had untolerated taint {node-role.kubernetes.io/XXXXXX: }. preemption: 0/5 nodes are available: 1 node(s) didn't match pod anti-affinity rules, 4 Preemption is not helpful for scheduling.."
2025-11-17T09:38:23.068527062Z I1117 09:38:23.068486       1 schedule_one.go:252] "Successfully bound pod to node" pod="openshift-monitoring/prometheus-operator-admission-webhook-686c664ffb-qdprf" node="XXXXXX1" evaluatedNodes=5 feasibleNodes=1
2025-11-17T09:38:23.072098313Z I1117 09:38:23.069048       1 schedule_one.go:252] "Successfully bound pod to node" pod="openshift-ingress/router-default-668949fb46-52qxp" node="XXXXXX1" evaluatedNodes=5 feasibleNodes=1
2025-11-17T09:38:23.150291630Z I1117 09:38:23.150247       1 schedule_one.go:252] "Successfully bound pod to node" pod="openshift-network-diagnostics/network-check-source-b56b967f4-6jv22" node="XXXXXX1" evaluatedNodes=5 feasibleNodes=1
2025-11-17T09:38:23.209813088Z I1117 09:38:23.209177       1 schedule_one.go:252] "Successfully bound pod to node" pod="openshift-operator-lifecycle-manager/collect-profiles-29389530-f4dqp" node="XXXXXX1" evaluatedNodes=5 feasibleNodes=1
2025-11-17T09:38:23.615824804Z I1117 09:38:23.615636       1 schedule_one.go:252] "Successfully bound pod to node" pod="openshift-dns/dns-default-fgdkx" node="XXXXXX0" evaluatedNodes=1 feasibleNodes=1
2025-11-17T09:38:23.783843178Z I1117 09:38:23.783804       1 schedule_one.go:252] "Successfully bound pod to node" pod="openshift-dns/dns-default-vmfrz" node="XXXXXX0" evaluatedNodes=1 feasibleNodes=1
2025-11-17T09:38:23.886364348Z I1117 09:38:23.886286       1 schedule_one.go:252] "Successfully bound pod to node" pod="openshift-dns/dns-default-62bnh" node="XXXXXX1" evaluatedNodes=1 feasibleNodes=1
2025-11-17T09:38:24.065342833Z I1117 09:38:24.065279       1 schedule_one.go:252] "Successfully bound pod to node" pod="openshift-ingress-canary/ingress-canary-kmbxv" node="XXXXXX0" evaluatedNodes=1 feasibleNodes=1
2025-11-17T09:38:24.307682043Z I1117 09:38:24.307259       1 schedule_one.go:252] "Successfully bound pod to node" pod="openshift-ingress-canary/ingress-canary-kzprm" node="XXXXXX1" evaluatedNodes=1 feasibleNodes=1
2025-11-17T09:38:25.563570337Z I1117 09:38:25.563102       1 schedule_one.go:252] "Successfully bound pod to node" pod="openshift-ingress/router-default-668949fb46-d6qkr" node="XXXXXX0" evaluatedNodes=5 feasibleNodes=1
2025-11-17T09:38:27.565229008Z I1117 09:38:27.565173       1 schedule_one.go:252] "Successfully bound pod to node" pod="openshift-monitoring/prometheus-operator-admission-webhook-686c664ffb-xlz8g" node="XXXXXX0" evaluatedNodes=5 feasibleNodes=1
2025-11-17T09:38:33.482407520Z I1117 09:38:33.482244       1 schedule_one.go:252] "Successfully bound pod to node" pod="openshift-authentication/oauth-openshift-76f996bb9d-wbblj" node="XXXXXX0" evaluatedNodes=5 feasibleNodes=3
2025-11-17T09:38:33.507286260Z I1117 09:38:33.507167       1 schedule_one.go:252] "Successfully bound pod to node" pod="openshift-authentication/oauth-openshift-76f996bb9d-9lf69" node="XXXXXX2" evaluatedNodes=5 feasibleNodes=1
2025-11-17T09:38:33.507286260Z I1117 09:38:33.507169       1 schedule_one.go:252] "Successfully bound pod to node" pod="openshift-authentication/oauth-openshift-76f996bb9d-cdbwh" node="XXXXXX1" evaluatedNodes=5 feasibleNodes=2
2025-11-17T09:38:36.447648238Z I1117 09:38:36.447383       1 schedule_one.go:252] "Successfully bound pod to node" pod="openshift-console/console-7959f94788-4rchz" node="XXXXXX0" evaluatedNodes=5 feasibleNodes=3
2025-11-17T09:38:36.458738227Z I1117 09:38:36.458658       1 schedule_one.go:252] "Successfully bound pod to node" pod="openshift-console/console-7959f94788-8mbqp" node="XXXXXX1" evaluatedNodes=5 feasibleNodes=2
2025-11-17T09:38:36.870117590Z I1117 09:38:36.870047       1 schedule_one.go:252] "Successfully bound pod to node" pod="openshift-monitoring/prometheus-operator-f9ccfd6c9-ht5ln" node="XXXXXX0" evaluatedNodes=5 feasibleNodes=3
2025-11-17T09:38:37.785955987Z I1117 09:38:37.785914       1 schedule_one.go:889] "Unable to schedule pod; no fit; waiting" pod="openshift-authentication/oauth-openshift-786998b97f-5d599" err="0/5 nodes are available: 2 node(s) didn't match Pod's node affinity/selector, 3 node(s) didn't match pod anti-affinity rules. preemption: 0/5 nodes are available: 2 Preemption is not helpful for scheduling, 3 node(s) didn't match pod anti-affinity rules.."
2025-11-17T09:38:41.936971501Z I1117 09:38:41.936913       1 schedule_one.go:889] "Unable to schedule pod; no fit; waiting" pod="openshift-authentication/oauth-openshift-786998b97f-5d599" err="0/5 nodes are available: 2 node(s) didn't match Pod's node affinity/selector, 3 node(s) didn't match pod anti-affinity rules. preemption: 0/5 nodes are available: 2 Preemption is not helpful for scheduling, 3 node(s) didn't match pod anti-affinity rules.."
2025-11-17T09:38:44.569569937Z I1117 09:38:44.569308       1 schedule_one.go:889] "Unable to schedule pod; no fit; waiting" pod="openshift-authentication/oauth-openshift-786998b97f-5d599" err="0/5 nodes are available: 2 node(s) didn't match Pod's node affinity/selector, 3 node(s) didn't match pod anti-affinity rules. preemption: 0/5 nodes are available: 2 Preemption is not helpful for scheduling, 3 node(s) didn't match pod anti-affinity rules.."
2025-11-17T09:38:45.460620543Z I1117 09:38:45.460511       1 schedule_one.go:252] "Successfully bound pod to node" pod="openshift-console/console-6876ff4cb4-hqnh8" node="XXXXXX2" evaluatedNodes=5 feasibleNodes=1
2025-11-17T09:38:45.461780652Z I1117 09:38:45.461556       1 schedule_one.go:889] "Unable to schedule pod; no fit; waiting" pod="openshift-console/console-6876ff4cb4-s96vh" err="0/5 nodes are available: 2 node(s) didn't match Pod's node affinity/selector, 3 node(s) didn't match pod anti-affinity rules. preemption: 0/5 nodes are available: 2 Preemption is not helpful for scheduling, 3 node(s) didn't match pod anti-affinity rules.."
2025-11-17T09:38:48.517498400Z I1117 09:38:48.517434       1 schedule_one.go:889] "Unable to schedule pod; no fit; waiting" pod="openshift-authentication/oauth-openshift-7d4fc55645-tq662" err="0/5 nodes are available: 2 node(s) didn't match Pod's node affinity/selector, 3 node(s) didn't match pod anti-affinity rules. preemption: 0/5 nodes are available: 2 Preemption is not helpful for scheduling, 3 node(s) didn't match pod anti-affinity rules.."
2025-11-17T09:38:49.752365435Z I1117 09:38:49.752315       1 schedule_one.go:889] "Unable to schedule pod; no fit; waiting" pod="openshift-authentication/oauth-openshift-786998b97f-5d599" err="0/5 nodes are available: 2 node(s) didn't match Pod's node affinity/selector, 3 node(s) didn't match pod anti-affinity rules. preemption: 0/5 nodes are available: 2 Preemption is not helpful for scheduling, 3 node(s) didn't match pod anti-affinity rules.."
2025-11-17T09:38:49.752774321Z I1117 09:38:49.752713       1 schedule_one.go:889] "Unable to schedule pod; no fit; waiting" pod="openshift-console/console-6876ff4cb4-s96vh" err="0/5 nodes are available: 2 node(s) didn't match Pod's node affinity/selector, 3 node(s) didn't match pod anti-affinity rules. preemption: 0/5 nodes are available: 2 Preemption is not helpful for scheduling, 3 node(s) didn't match pod anti-affinity rules.."
2025-11-17T09:38:49.753082497Z I1117 09:38:49.753043       1 schedule_one.go:889] "Unable to schedule pod; no fit; waiting" pod="openshift-authentication/oauth-openshift-7d4fc55645-tq662" err="0/5 nodes are available: 2 node(s) didn't match Pod's node affinity/selector, 3 node(s) didn't match pod anti-affinity rules. preemption: 0/5 nodes are available: 2 Preemption is not helpful for scheduling, 3 node(s) didn't match pod anti-affinity rules.."
2025-11-17T09:38:51.089152751Z I1117 09:38:51.088594       1 schedule_one.go:252] "Successfully bound pod to node" pod="openshift-monitoring/monitoring-plugin-7b5d6d66c-mxrkd" node="XXXXXX1" evaluatedNodes=5 feasibleNodes=2
2025-11-17T09:38:51.104389971Z I1117 09:38:51.104059       1 schedule_one.go:252] "Successfully bound pod to node" pod="openshift-monitoring/monitoring-plugin-7b5d6d66c-k6f6m" node="XXXXXX0" evaluatedNodes=5 feasibleNodes=1
2025-11-17T09:38:51.271718185Z I1117 09:38:51.271657       1 schedule_one.go:252] "Successfully bound pod to node" pod="openshift-monitoring/openshift-state-metrics-fb74d4bc4-q2ssp" node="XXXXXX1" evaluatedNodes=5 feasibleNodes=2
2025-11-17T09:38:51.272167737Z I1117 09:38:51.272133       1 schedule_one.go:252] "Successfully bound pod to node" pod="openshift-monitoring/kube-state-metrics-688f695dcc-5xxjr" node="XXXXXX1" evaluatedNodes=5 feasibleNodes=2
2025-11-17T09:38:51.294321727Z I1117 09:38:51.293275       1 schedule_one.go:252] "Successfully bound pod to node" pod="openshift-monitoring/node-exporter-x4xx4" node="XXXXXX0" evaluatedNodes=1 feasibleNodes=1
2025-11-17T09:38:51.316634301Z I1117 09:38:51.315674       1 schedule_one.go:252] "Successfully bound pod to node" pod="openshift-monitoring/node-exporter-2xsjl" node="XXXXXX2" evaluatedNodes=1 feasibleNodes=1
2025-11-17T09:38:51.316634301Z I1117 09:38:51.316060       1 schedule_one.go:252] "Successfully bound pod to node" pod="openshift-monitoring/node-exporter-mbvln" node="XXXXXX1" evaluatedNodes=1 feasibleNodes=1
2025-11-17T09:38:51.342427641Z I1117 09:38:51.341735       1 schedule_one.go:252] "Successfully bound pod to node" pod="openshift-monitoring/node-exporter-7sftb" node="XXXXXX1" evaluatedNodes=1 feasibleNodes=1
2025-11-17T09:38:51.349250397Z I1117 09:38:51.349157       1 schedule_one.go:252] "Successfully bound pod to node" pod="openshift-monitoring/node-exporter-kwg8s" node="XXXXXX0" evaluatedNodes=1 feasibleNodes=1
2025-11-17T09:38:53.805898097Z I1117 09:38:53.805819       1 schedule_one.go:252] "Successfully bound pod to node" pod="openshift-monitoring/prometheus-adapter-5d757bbd4b-rm9nc" node="XXXXXX1" evaluatedNodes=5 feasibleNodes=2
2025-11-17T09:38:53.820714303Z I1117 09:38:53.820518       1 schedule_one.go:252] "Successfully bound pod to node" pod="openshift-monitoring/prometheus-adapter-5d757bbd4b-hr9ql" node="XXXXXX0" evaluatedNodes=5 feasibleNodes=1
2025-11-17T09:38:56.540814070Z I1117 09:38:56.538748       1 schedule_one.go:252] "Successfully bound pod to node" pod="openshift-monitoring/telemeter-client-7bb98fb6bc-ptrbd" node="XXXXXX1" evaluatedNodes=5 feasibleNodes=2
2025-11-17T09:38:57.324887211Z I1117 09:38:57.324219       1 schedule_one.go:252] "Successfully bound pod to node" pod="openshift-monitoring/alertmanager-main-0" node="XXXXXX1" evaluatedNodes=5 feasibleNodes=2
2025-11-17T09:38:57.345290685Z I1117 09:38:57.345213       1 schedule_one.go:252] "Successfully bound pod to node" pod="openshift-monitoring/alertmanager-main-1" node="XXXXXX0" evaluatedNodes=5 feasibleNodes=1
2025-11-17T09:38:57.800092097Z I1117 09:38:57.800028       1 schedule_one.go:889] "Unable to schedule pod; no fit; waiting" pod="openshift-authentication/oauth-openshift-786998b97f-5d599" err="0/5 nodes are available: 2 node(s) didn't match Pod's node affinity/selector, 3 node(s) didn't match pod anti-affinity rules. preemption: 0/5 nodes are available: 2 Preemption is not helpful for scheduling, 3 node(s) didn't match pod anti-affinity rules.."
2025-11-17T09:38:57.800485473Z I1117 09:38:57.800454       1 schedule_one.go:889] "Unable to schedule pod; no fit; waiting" pod="openshift-console/console-6876ff4cb4-s96vh" err="0/5 nodes are available: 2 node(s) didn't match Pod's node affinity/selector, 3 node(s) didn't match pod anti-affinity rules. preemption: 0/5 nodes are available: 2 Preemption is not helpful for scheduling, 3 node(s) didn't match pod anti-affinity rules.."
2025-11-17T09:38:57.801174286Z I1117 09:38:57.801146       1 schedule_one.go:889] "Unable to schedule pod; no fit; waiting" pod="openshift-authentication/oauth-openshift-7d4fc55645-tq662" err="0/5 nodes are available: 2 node(s) didn't match Pod's node affinity/selector, 3 node(s) didn't match pod anti-affinity rules. preemption: 0/5 nodes are available: 2 Preemption is not helpful for scheduling, 3 node(s) didn't match pod anti-affinity rules.."
2025-11-17T09:38:57.843833092Z I1117 09:38:57.840533       1 schedule_one.go:889] "Unable to schedule pod; no fit; waiting" pod="openshift-console/console-595d4b756b-f6fvd" err="0/5 nodes are available: 2 node(s) didn't match Pod's node affinity/selector, 3 node(s) didn't match pod anti-affinity rules. preemption: 0/5 nodes are available: 2 Preemption is not helpful for scheduling, 3 node(s) didn't match pod anti-affinity rules.."
2025-11-17T09:38:57.853462418Z I1117 09:38:57.853411       1 schedule_one.go:889] "Unable to schedule pod; no fit; waiting" pod="openshift-console/console-595d4b756b-xlhtg" err="0/5 nodes are available: 2 node(s) didn't match Pod's node affinity/selector, 3 node(s) didn't match pod anti-affinity rules. preemption: 0/5 nodes are available: 2 Preemption is not helpful for scheduling, 3 node(s) didn't match pod anti-affinity rules.."
2025-11-17T09:38:58.765910892Z I1117 09:38:58.765212       1 schedule_one.go:252] "Successfully bound pod to node" pod="openshift-monitoring/thanos-querier-95bdbdd77-7dzg4" node="XXXXXX1" evaluatedNodes=5 feasibleNodes=2
2025-11-17T09:38:58.783306353Z I1117 09:38:58.782985       1 schedule_one.go:252] "Successfully bound pod to node" pod="openshift-monitoring/thanos-querier-95bdbdd77-wnqt4" node="XXXXXX0" evaluatedNodes=5 feasibleNodes=1
2025-11-17T09:39:02.746067298Z I1117 09:39:02.746010       1 schedule_one.go:252] "Successfully bound pod to node" pod="openshift-monitoring/prometheus-k8s-0" node="XXXXXX0" evaluatedNodes=5 feasibleNodes=2
2025-11-17T09:39:02.760682831Z I1117 09:39:02.760620       1 schedule_one.go:252] "Successfully bound pod to node" pod="openshift-monitoring/prometheus-k8s-1" node="XXXXXX1" evaluatedNodes=5 feasibleNodes=1
2025-11-17T09:39:10.320502477Z I1117 09:39:10.320063       1 schedule_one.go:889] "Unable to schedule pod; no fit; waiting" pod="openshift-authentication/oauth-openshift-786998b97f-5d599" err="0/5 nodes are available: 2 node(s) didn't match Pod's node affinity/selector, 3 node(s) didn't match pod anti-affinity rules. preemption: 0/5 nodes are available: 2 Preemption is not helpful for scheduling, 3 node(s) didn't match pod anti-affinity rules.."
2025-11-17T09:39:10.320651095Z I1117 09:39:10.320587       1 schedule_one.go:889] "Unable to schedule pod; no fit; waiting" pod="openshift-authentication/oauth-openshift-7d4fc55645-tq662" err="0/5 nodes are available: 2 node(s) didn't match Pod's node affinity/selector, 3 node(s) didn't match pod anti-affinity rules. preemption: 0/5 nodes are available: 2 Preemption is not helpful for scheduling, 3 node(s) didn't match pod anti-affinity rules.."
2025-11-17T09:39:10.321184962Z I1117 09:39:10.321149       1 schedule_one.go:889] "Unable to schedule pod; no fit; waiting" pod="openshift-console/console-595d4b756b-f6fvd" err="0/5 nodes are available: 2 node(s) didn't match Pod's node affinity/selector, 3 node(s) didn't match pod anti-affinity rules. preemption: 0/5 nodes are available: 2 Preemption is not helpful for scheduling, 3 node(s) didn't match pod anti-affinity rules.."
2025-11-17T09:39:10.321663910Z I1117 09:39:10.321642       1 schedule_one.go:889] "Unable to schedule pod; no fit; waiting" pod="openshift-console/console-595d4b756b-xlhtg" err="0/5 nodes are available: 2 node(s) didn't match Pod's node affinity/selector, 3 node(s) didn't match pod anti-affinity rules. preemption: 0/5 nodes are available: 2 Preemption is not helpful for scheduling, 3 node(s) didn't match pod anti-affinity rules.."
2025-11-17T09:39:13.864575746Z I1117 09:39:13.864533       1 schedule_one.go:889] "Unable to schedule pod; no fit; waiting" pod="openshift-console/console-595d4b756b-f6fvd" err="0/5 nodes are available: 2 node(s) didn't match Pod's node affinity/selector, 3 node(s) didn't match pod anti-affinity rules. preemption: 0/5 nodes are available: 2 Preemption is not helpful for scheduling, 3 node(s) didn't match pod anti-affinity rules.."
2025-11-17T09:39:13.865335122Z I1117 09:39:13.865290       1 schedule_one.go:889] "Unable to schedule pod; no fit; waiting" pod="openshift-console/console-595d4b756b-xlhtg" err="0/5 nodes are available: 2 node(s) didn't match Pod's node affinity/selector, 3 node(s) didn't match pod anti-affinity rules. preemption: 0/5 nodes are available: 2 Preemption is not helpful for scheduling, 3 node(s) didn't match pod anti-affinity rules.."
2025-11-17T09:39:18.061625413Z I1117 09:39:18.061579       1 schedule_one.go:889] "Unable to schedule pod; no fit; waiting" pod="openshift-console/console-595d4b756b-xlhtg" err="0/5 nodes are available: 2 node(s) didn't match Pod's node affinity/selector, 3 node(s) didn't match pod anti-affinity rules. preemption: 0/5 nodes are available: 2 Preemption is not helpful for scheduling, 3 node(s) didn't match pod anti-affinity rules.."
2025-11-17T09:39:18.067177104Z I1117 09:39:18.067143       1 schedule_one.go:252] "Successfully bound pod to node" pod="openshift-console/console-595d4b756b-f6fvd" node="XXXXXX0" evaluatedNodes=5 feasibleNodes=1
2025-11-17T09:39:18.587296039Z I1117 09:39:18.587244       1 schedule_one.go:889] "Unable to schedule pod; no fit; waiting" pod="openshift-authentication/oauth-openshift-7d4fc55645-tq662" err="0/5 nodes are available: 2 node(s) didn't match Pod's node affinity/selector, 3 node(s) didn't match pod anti-affinity rules. preemption: 0/5 nodes are available: 2 Preemption is not helpful for scheduling, 3 node(s) didn't match pod anti-affinity rules.."
2025-11-17T09:39:20.588843857Z I1117 09:39:20.588790       1 schedule_one.go:889] "Unable to schedule pod; no fit; waiting" pod="openshift-authentication/oauth-openshift-786998b97f-5d599" err="0/5 nodes are available: 2 node(s) didn't match Pod's node affinity/selector, 3 node(s) didn't match pod anti-affinity rules. preemption: 0/5 nodes are available: 2 Preemption is not helpful for scheduling, 3 node(s) didn't match pod anti-affinity rules.."
2025-11-17T09:39:26.597985187Z I1117 09:39:26.597879       1 schedule_one.go:252] "Successfully bound pod to node" pod="openshift-console/console-595d4b756b-xlhtg" node="XXXXXX1" evaluatedNodes=5 feasibleNodes=1
2025-11-17T09:39:28.599962165Z I1117 09:39:28.599890       1 schedule_one.go:252] "Successfully bound pod to node" pod="openshift-authentication/oauth-openshift-7d4fc55645-tq662" node="XXXXXX0" evaluatedNodes=5 feasibleNodes=2
2025-11-17T09:39:30.602183254Z I1117 09:39:30.601946       1 schedule_one.go:252] "Successfully bound pod to node" pod="openshift-authentication/oauth-openshift-786998b97f-5d599" node="XXXXXX1" evaluatedNodes=5 feasibleNodes=1
2025-11-17T09:39:33.883485922Z I1117 09:39:33.883412       1 schedule_one.go:889] "Unable to schedule pod; no fit; waiting" pod="openshift-authentication/oauth-openshift-7d4fc55645-9t4xf" err="0/5 nodes are available: 2 node(s) didn't match Pod's node affinity/selector, 3 node(s) didn't match pod anti-affinity rules. preemption: 0/5 nodes are available: 2 Preemption is not helpful for scheduling, 3 node(s) didn't match pod anti-affinity rules.."
2025-11-17T09:39:37.982923061Z I1117 09:39:37.982865       1 schedule_one.go:889] "Unable to schedule pod; no fit; waiting" pod="openshift-authentication/oauth-openshift-7d4fc55645-9t4xf" err="0/5 nodes are available: 2 node(s) didn't match Pod's node affinity/selector, 3 node(s) didn't match pod anti-affinity rules. preemption: 0/5 nodes are available: 2 Preemption is not helpful for scheduling, 3 node(s) didn't match pod anti-affinity rules.."
2025-11-17T09:39:45.893546672Z I1117 09:39:45.893485       1 schedule_one.go:889] "Unable to schedule pod; no fit; waiting" pod="openshift-oauth-apiserver/apiserver-59b5566b46-bmmgt" err="0/5 nodes are available: 2 node(s) didn't match Pod's node affinity/selector, 3 node(s) didn't match pod anti-affinity rules. preemption: 0/5 nodes are available: 2 Preemption is not helpful for scheduling, 3 node(s) didn't match pod anti-affinity rules.."
2025-11-17T09:39:47.258537744Z I1117 09:39:47.255770       1 schedule_one.go:889] "Unable to schedule pod; no fit; waiting" pod="openshift-oauth-apiserver/apiserver-59b5566b46-bmmgt" err="0/5 nodes are available: 2 node(s) didn't match Pod's node affinity/selector, 3 node(s) didn't match pod anti-affinity rules. preemption: 0/5 nodes are available: 2 Preemption is not helpful for scheduling, 3 node(s) didn't match pod anti-affinity rules.."
2025-11-17T09:39:47.258537744Z I1117 09:39:47.256327       1 schedule_one.go:889] "Unable to schedule pod; no fit; waiting" pod="openshift-authentication/oauth-openshift-7d4fc55645-9t4xf" err="0/5 nodes are available: 2 node(s) didn't match Pod's node affinity/selector, 3 node(s) didn't match pod anti-affinity rules. preemption: 0/5 nodes are available: 2 Preemption is not helpful for scheduling, 3 node(s) didn't match pod anti-affinity rules.."
2025-11-17T09:39:59.256441253Z I1117 09:39:59.256361       1 schedule_one.go:889] "Unable to schedule pod; no fit; waiting" pod="openshift-oauth-apiserver/apiserver-59b5566b46-bmmgt" err="0/5 nodes are available: 2 node(s) didn't match Pod's node affinity/selector, 3 node(s) didn't match pod anti-affinity rules. preemption: 0/5 nodes are available: 2 Preemption is not helpful for scheduling, 3 node(s) didn't match pod anti-affinity rules.."
2025-11-17T09:39:59.266202365Z I1117 09:39:59.266137       1 schedule_one.go:252] "Successfully bound pod to node" pod="openshift-authentication/oauth-openshift-7d4fc55645-9t4xf" node="XXXXXX2" evaluatedNodes=5 feasibleNodes=1
2025-11-17T09:40:01.980298533Z I1117 09:40:01.979997       1 schedule_one.go:889] "Unable to schedule pod; no fit; waiting" pod="openshift-console/console-69dbd9bdf7-kbtj6" err="0/5 nodes are available: 2 node(s) didn't match Pod's node affinity/selector, 3 node(s) didn't match pod anti-affinity rules. preemption: 0/5 nodes are available: 2 Preemption is not helpful for scheduling, 3 node(s) didn't match pod anti-affinity rules.."
2025-11-17T09:40:02.000455512Z I1117 09:40:02.000393       1 schedule_one.go:889] "Unable to schedule pod; no fit; waiting" pod="openshift-console/console-69dbd9bdf7-4hrtl" err="0/5 nodes are available: 2 node(s) didn't match Pod's node affinity/selector, 3 node(s) didn't match pod anti-affinity rules. preemption: 0/5 nodes are available: 2 Preemption is not helpful for scheduling, 3 node(s) didn't match pod anti-affinity rules.."
2025-11-17T09:40:02.672396421Z I1117 09:40:02.672060       1 schedule_one.go:889] "Unable to schedule pod; no fit; waiting" pod="openshift-apiserver/apiserver-844688b4f5-j557c" err="0/5 nodes are available: 2 node(s) didn't match Pod's node affinity/selector, 3 node(s) didn't match pod anti-affinity rules. preemption: 0/5 nodes are available: 2 Preemption is not helpful for scheduling, 3 node(s) didn't match pod anti-affinity rules.."
2025-11-17T09:40:03.084383212Z I1117 09:40:03.084322       1 schedule_one.go:889] "Unable to schedule pod; no fit; waiting" pod="openshift-console/console-69dbd9bdf7-kbtj6" err="0/5 nodes are available: 2 node(s) didn't match Pod's node affinity/selector, 3 node(s) didn't match pod anti-affinity rules. preemption: 0/5 nodes are available: 2 Preemption is not helpful for scheduling, 3 node(s) didn't match pod anti-affinity rules.."
2025-11-17T09:40:03.085409532Z I1117 09:40:03.085245       1 schedule_one.go:889] "Unable to schedule pod; no fit; waiting" pod="openshift-console/console-69dbd9bdf7-4hrtl" err="0/5 nodes are available: 2 node(s) didn't match Pod's node affinity/selector, 3 node(s) didn't match pod anti-affinity rules. preemption: 0/5 nodes are available: 2 Preemption is not helpful for scheduling, 3 node(s) didn't match pod anti-affinity rules.."
2025-11-17T09:40:03.548829427Z I1117 09:40:03.548307       1 schedule_one.go:889] "Unable to schedule pod; no fit; waiting" pod="openshift-authentication/oauth-openshift-7d4fc55645-h42dm" err="0/5 nodes are available: 2 node(s) didn't match Pod's node affinity/selector, 3 node(s) didn't match pod anti-affinity rules. preemption: 0/5 nodes are available: 2 Preemption is not helpful for scheduling, 3 node(s) didn't match pod anti-affinity rules.."
2025-11-17T09:40:03.625105159Z I1117 09:40:03.624749       1 schedule_one.go:252] "Successfully bound pod to node" pod="openshift-oauth-apiserver/apiserver-59b5566b46-bmmgt" node="XXXXXX0" evaluatedNodes=5 feasibleNodes=1
2025-11-17T09:40:04.037642710Z I1117 09:40:04.037579       1 schedule_one.go:252] "Successfully bound pod to node" pod="openshift-monitoring/alertmanager-main-1" node="XXXXXX0" evaluatedNodes=5 feasibleNodes=1
2025-11-17T09:40:04.613211355Z I1117 09:40:04.613146       1 schedule_one.go:889] "Unable to schedule pod; no fit; waiting" pod="openshift-apiserver/apiserver-844688b4f5-j557c" err="0/5 nodes are available: 2 node(s) didn't match Pod's node affinity/selector, 3 node(s) didn't match pod anti-affinity rules. preemption: 0/5 nodes are available: 2 Preemption is not helpful for scheduling, 3 node(s) didn't match pod anti-affinity rules.."
2025-11-17T09:40:04.660752438Z I1117 09:40:04.660680       1 schedule_one.go:889] "Unable to schedule pod; no fit; waiting" pod="openshift-authentication/oauth-openshift-7d4fc55645-h42dm" err="0/5 nodes are available: 2 node(s) didn't match Pod's node affinity/selector, 3 node(s) didn't match pod anti-affinity rules. preemption: 0/5 nodes are available: 2 Preemption is not helpful for scheduling, 3 node(s) didn't match pod anti-affinity rules.."
2025-11-17T09:40:05.613649414Z I1117 09:40:05.613584       1 schedule_one.go:889] "Unable to schedule pod; no fit; waiting" pod="openshift-console/console-69dbd9bdf7-kbtj6" err="0/5 nodes are available: 2 node(s) didn't match Pod's node affinity/selector, 3 node(s) didn't match pod anti-affinity rules. preemption: 0/5 nodes are available: 2 Preemption is not helpful for scheduling, 3 node(s) didn't match pod anti-affinity rules.."
2025-11-17T09:40:05.614146145Z I1117 09:40:05.614088       1 schedule_one.go:889] "Unable to schedule pod; no fit; waiting" pod="openshift-console/console-69dbd9bdf7-4hrtl" err="0/5 nodes are available: 2 node(s) didn't match Pod's node affinity/selector, 3 node(s) didn't match pod anti-affinity rules. preemption: 0/5 nodes are available: 2 Preemption is not helpful for scheduling, 3 node(s) didn't match pod anti-affinity rules.."
2025-11-17T09:40:07.615648208Z I1117 09:40:07.615479       1 schedule_one.go:889] "Unable to schedule pod; no fit; waiting" pod="openshift-apiserver/apiserver-844688b4f5-j557c" err="0/5 nodes are available: 2 node(s) didn't match Pod's node affinity/selector, 3 node(s) didn't match pod anti-affinity rules. preemption: 0/5 nodes are available: 2 Preemption is not helpful for scheduling, 3 node(s) didn't match pod anti-affinity rules.."
2025-11-17T09:40:07.883183853Z I1117 09:40:07.883118       1 schedule_one.go:889] "Unable to schedule pod; no fit; waiting" pod="openshift-authentication/oauth-openshift-7d4fc55645-h42dm" err="0/5 nodes are available: 2 node(s) didn't match Pod's node affinity/selector, 3 node(s) didn't match pod anti-affinity rules. preemption: 0/5 nodes are available: 2 Preemption is not helpful for scheduling, 3 node(s) didn't match pod anti-affinity rules.."
2025-11-17T09:40:08.918880101Z I1117 09:40:08.918813       1 schedule_one.go:252] "Successfully bound pod to node" pod="openshift-monitoring/prometheus-k8s-1" node="XXXXXX1" evaluatedNodes=5 feasibleNodes=1
2025-11-17T09:40:09.615743005Z I1117 09:40:09.615673       1 schedule_one.go:889] "Unable to schedule pod; no fit; waiting" pod="openshift-console/console-69dbd9bdf7-kbtj6" err="0/5 nodes are available: 2 node(s) didn't match Pod's node affinity/selector, 3 node(s) didn't match pod anti-affinity rules. preemption: 0/5 nodes are available: 2 Preemption is not helpful for scheduling, 3 node(s) didn't match pod anti-affinity rules.."
2025-11-17T09:40:09.616035244Z I1117 09:40:09.616020       1 schedule_one.go:889] "Unable to schedule pod; no fit; waiting" pod="openshift-console/console-69dbd9bdf7-4hrtl" err="0/5 nodes are available: 2 node(s) didn't match Pod's node affinity/selector, 3 node(s) didn't match pod anti-affinity rules. preemption: 0/5 nodes are available: 2 Preemption is not helpful for scheduling, 3 node(s) didn't match pod anti-affinity rules.."
2025-11-17T09:40:10.026161723Z I1117 09:40:10.025458       1 schedule_one.go:889] "Unable to schedule pod; no fit; waiting" pod="openshift-oauth-apiserver/apiserver-59b5566b46-llw7k" err="0/5 nodes are available: 2 node(s) didn't match Pod's node affinity/selector, 3 node(s) didn't match pod anti-affinity rules. preemption: 0/5 nodes are available: 2 Preemption is not helpful for scheduling, 3 node(s) didn't match pod anti-affinity rules.."
2025-11-17T09:40:11.617959321Z I1117 09:40:11.617912       1 schedule_one.go:889] "Unable to schedule pod; no fit; waiting" pod="openshift-apiserver/apiserver-844688b4f5-j557c" err="0/5 nodes are available: 2 node(s) didn't match Pod's node affinity/selector, 3 node(s) didn't match pod anti-affinity rules. preemption: 0/5 nodes are available: 2 Preemption is not helpful for scheduling, 3 node(s) didn't match pod anti-affinity rules.."
2025-11-17T09:40:12.131071084Z I1117 09:40:12.130548       1 schedule_one.go:889] "Unable to schedule pod; no fit; waiting" pod="openshift-oauth-apiserver/apiserver-59b5566b46-llw7k" err="0/5 nodes are available: 2 node(s) didn't match Pod's node affinity/selector, 3 node(s) didn't match pod anti-affinity rules. preemption: 0/5 nodes are available: 2 Preemption is not helpful for scheduling, 3 node(s) didn't match pod anti-affinity rules.."
2025-11-17T09:40:12.618363262Z I1117 09:40:12.618313       1 schedule_one.go:889] "Unable to schedule pod; no fit; waiting" pod="openshift-authentication/oauth-openshift-7d4fc55645-h42dm" err="0/5 nodes are available: 2 node(s) didn't match Pod's node affinity/selector, 3 node(s) didn't match pod anti-affinity rules. preemption: 0/5 nodes are available: 2 Preemption is not helpful for scheduling, 3 node(s) didn't match pod anti-affinity rules.."
2025-11-17T09:40:16.493738953Z I1117 09:40:16.493673       1 schedule_one.go:889] "Unable to schedule pod; no fit; waiting" pod="openshift-oauth-apiserver/apiserver-59b5566b46-llw7k" err="0/5 nodes are available: 2 node(s) didn't match Pod's node affinity/selector, 3 node(s) didn't match pod anti-affinity rules. preemption: 0/5 nodes are available: 2 Preemption is not helpful for scheduling, 3 node(s) didn't match pod anti-affinity rules.."
2025-11-17T09:40:17.621534684Z I1117 09:40:17.621451       1 schedule_one.go:889] "Unable to schedule pod; no fit; waiting" pod="openshift-console/console-69dbd9bdf7-kbtj6" err="0/5 nodes are available: 2 node(s) didn't match Pod's node affinity/selector, 3 node(s) didn't match pod anti-affinity rules. preemption: 0/5 nodes are available: 2 Preemption is not helpful for scheduling, 3 node(s) didn't match pod anti-affinity rules.."
2025-11-17T09:40:17.621798150Z I1117 09:40:17.621770       1 schedule_one.go:889] "Unable to schedule pod; no fit; waiting" pod="openshift-console/console-69dbd9bdf7-4hrtl" err="0/5 nodes are available: 2 node(s) didn't match Pod's node affinity/selector, 3 node(s) didn't match pod anti-affinity rules. preemption: 0/5 nodes are available: 2 Preemption is not helpful for scheduling, 3 node(s) didn't match pod anti-affinity rules.."
2025-11-17T09:40:19.622968873Z I1117 09:40:19.622923       1 schedule_one.go:889] "Unable to schedule pod; no fit; waiting" pod="openshift-apiserver/apiserver-844688b4f5-j557c" err="0/5 nodes are available: 2 node(s) didn't match Pod's node affinity/selector, 3 node(s) didn't match pod anti-affinity rules. preemption: 0/5 nodes are available: 2 Preemption is not helpful for scheduling, 3 node(s) didn't match pod anti-affinity rules.."
2025-11-17T09:40:20.623971824Z I1117 09:40:20.623919       1 schedule_one.go:889] "Unable to schedule pod; no fit; waiting" pod="openshift-authentication/oauth-openshift-7d4fc55645-h42dm" err="0/5 nodes are available: 2 node(s) didn't match Pod's node affinity/selector, 3 node(s) didn't match pod anti-affinity rules. preemption: 0/5 nodes are available: 2 Preemption is not helpful for scheduling, 3 node(s) didn't match pod anti-affinity rules.."
2025-11-17T09:40:20.776975448Z I1117 09:40:20.776919       1 schedule_one.go:889] "Unable to schedule pod; no fit; waiting" pod="openshift-oauth-apiserver/apiserver-59b5566b46-llw7k" err="0/5 nodes are available: 2 node(s) didn't match Pod's node affinity/selector, 3 node(s) didn't match pod anti-affinity rules. preemption: 0/5 nodes are available: 2 Preemption is not helpful for scheduling, 3 node(s) didn't match pod anti-affinity rules.."
2025-11-17T09:40:26.108527330Z I1117 09:40:26.108438       1 schedule_one.go:252] "Successfully bound pod to node" pod="openshift-monitoring/prometheus-k8s-0" node="XXXXXX0" evaluatedNodes=5 feasibleNodes=1
2025-11-17T09:40:27.634419446Z I1117 09:40:27.634355       1 schedule_one.go:252] "Successfully bound pod to node" pod="openshift-console/console-69dbd9bdf7-4hrtl" node="XXXXXX2" evaluatedNodes=5 feasibleNodes=1
2025-11-17T09:40:27.634502484Z I1117 09:40:27.634371       1 schedule_one.go:252] "Successfully bound pod to node" pod="openshift-console/console-69dbd9bdf7-kbtj6" node="XXXXXX0" evaluatedNodes=5 feasibleNodes=2
2025-11-17T09:40:29.628702907Z I1117 09:40:29.628629       1 schedule_one.go:889] "Unable to schedule pod; no fit; waiting" pod="openshift-apiserver/apiserver-844688b4f5-j557c" err="0/5 nodes are available: 2 node(s) didn't match Pod's node affinity/selector, 3 node(s) didn't match pod anti-affinity rules. preemption: 0/5 nodes are available: 2 Preemption is not helpful for scheduling, 3 node(s) didn't match pod anti-affinity rules.."
2025-11-17T09:40:29.629144275Z I1117 09:40:29.629121       1 schedule_one.go:889] "Unable to schedule pod; no fit; waiting" pod="openshift-oauth-apiserver/apiserver-59b5566b46-llw7k" err="0/5 nodes are available: 2 node(s) didn't match Pod's node affinity/selector, 3 node(s) didn't match pod anti-affinity rules. preemption: 0/5 nodes are available: 2 Preemption is not helpful for scheduling, 3 node(s) didn't match pod anti-affinity rules.."
2025-11-17T09:40:30.633889164Z I1117 09:40:30.633821       1 schedule_one.go:252] "Successfully bound pod to node" pod="openshift-authentication/oauth-openshift-7d4fc55645-h42dm" node="XXXXXX1" evaluatedNodes=5 feasibleNodes=1
2025-11-17T09:40:35.992130647Z I1117 09:40:35.991978       1 schedule_one.go:252] "Successfully bound pod to node" pod="openshift-monitoring/alertmanager-main-0" node="XXXXXX1" evaluatedNodes=5 feasibleNodes=1
2025-11-17T09:40:39.632576064Z I1117 09:40:39.632518       1 schedule_one.go:889] "Unable to schedule pod; no fit; waiting" pod="openshift-apiserver/apiserver-844688b4f5-j557c" err="0/5 nodes are available: 2 node(s) didn't match Pod's node affinity/selector, 3 node(s) didn't match pod anti-affinity rules. preemption: 0/5 nodes are available: 2 Preemption is not helpful for scheduling, 3 node(s) didn't match pod anti-affinity rules.."
2025-11-17T09:40:39.633151933Z I1117 09:40:39.633129       1 schedule_one.go:889] "Unable to schedule pod; no fit; waiting" pod="openshift-oauth-apiserver/apiserver-59b5566b46-llw7k" err="0/5 nodes are available: 2 node(s) didn't match Pod's node affinity/selector, 3 node(s) didn't match pod anti-affinity rules. preemption: 0/5 nodes are available: 2 Preemption is not helpful for scheduling, 3 node(s) didn't match pod anti-affinity rules.."
2025-11-17T09:40:49.638391314Z I1117 09:40:49.638343       1 schedule_one.go:889] "Unable to schedule pod; no fit; waiting" pod="openshift-apiserver/apiserver-844688b4f5-j557c" err="0/5 nodes are available: 2 node(s) didn't match Pod's node affinity/selector, 3 node(s) didn't match pod anti-affinity rules. preemption: 0/5 nodes are available: 2 Preemption is not helpful for scheduling, 3 node(s) didn't match pod anti-affinity rules.."
2025-11-17T09:40:49.638837284Z I1117 09:40:49.638816       1 schedule_one.go:889] "Unable to schedule pod; no fit; waiting" pod="openshift-oauth-apiserver/apiserver-59b5566b46-llw7k" err="0/5 nodes are available: 2 node(s) didn't match Pod's node affinity/selector, 3 node(s) didn't match pod anti-affinity rules. preemption: 0/5 nodes are available: 2 Preemption is not helpful for scheduling, 3 node(s) didn't match pod anti-affinity rules.."
2025-11-17T09:40:59.644014115Z I1117 09:40:59.643925       1 schedule_one.go:889] "Unable to schedule pod; no fit; waiting" pod="openshift-apiserver/apiserver-844688b4f5-j557c" err="0/5 nodes are available: 2 node(s) didn't match Pod's node affinity/selector, 3 node(s) didn't match pod anti-affinity rules. preemption: 0/5 nodes are available: 2 Preemption is not helpful for scheduling, 3 node(s) didn't match pod anti-affinity rules.."
2025-11-17T09:40:59.644486089Z I1117 09:40:59.644452       1 schedule_one.go:889] "Unable to schedule pod; no fit; waiting" pod="openshift-oauth-apiserver/apiserver-59b5566b46-llw7k" err="0/5 nodes are available: 2 node(s) didn't match Pod's node affinity/selector, 3 node(s) didn't match pod anti-affinity rules. preemption: 0/5 nodes are available: 2 Preemption is not helpful for scheduling, 3 node(s) didn't match pod anti-affinity rules.."
2025-11-17T09:41:09.648114803Z I1117 09:41:09.648069       1 schedule_one.go:889] "Unable to schedule pod; no fit; waiting" pod="openshift-apiserver/apiserver-844688b4f5-j557c" err="0/5 nodes are available: 2 node(s) didn't match Pod's node affinity/selector, 3 node(s) didn't match pod anti-affinity rules. preemption: 0/5 nodes are available: 2 Preemption is not helpful for scheduling, 3 node(s) didn't match pod anti-affinity rules.."
2025-11-17T09:41:09.648591202Z I1117 09:41:09.648552       1 schedule_one.go:889] "Unable to schedule pod; no fit; waiting" pod="openshift-oauth-apiserver/apiserver-59b5566b46-llw7k" err="0/5 nodes are available: 2 node(s) didn't match Pod's node affinity/selector, 3 node(s) didn't match pod anti-affinity rules. preemption: 0/5 nodes are available: 2 Preemption is not helpful for scheduling, 3 node(s) didn't match pod anti-affinity rules.."
2025-11-17T09:41:19.659626770Z I1117 09:41:19.659590       1 schedule_one.go:252] "Successfully bound pod to node" pod="openshift-apiserver/apiserver-844688b4f5-j557c" node="XXXXXX0" evaluatedNodes=5 feasibleNodes=1
2025-11-17T09:41:19.662757372Z I1117 09:41:19.661494       1 schedule_one.go:252] "Successfully bound pod to node" pod="openshift-oauth-apiserver/apiserver-59b5566b46-llw7k" node="XXXXXX2" evaluatedNodes=5 feasibleNodes=1
2025-11-17T09:41:26.078944768Z I1117 09:41:26.078566       1 schedule_one.go:889] "Unable to schedule pod; no fit; waiting" pod="openshift-oauth-apiserver/apiserver-59b5566b46-czsqx" err="0/5 nodes are available: 2 node(s) didn't match Pod's node affinity/selector, 3 node(s) didn't match pod anti-affinity rules. preemption: 0/5 nodes are available: 2 Preemption is not helpful for scheduling, 3 node(s) didn't match pod anti-affinity rules.."
2025-11-17T09:41:30.426725485Z I1117 09:41:30.426163       1 schedule_one.go:889] "Unable to schedule pod; no fit; waiting" pod="openshift-apiserver/apiserver-844688b4f5-gcqpj" err="0/5 nodes are available: 2 node(s) didn't match Pod's node affinity/selector, 3 node(s) didn't match pod anti-affinity rules. preemption: 0/5 nodes are available: 2 Preemption is not helpful for scheduling, 3 node(s) didn't match pod anti-affinity rules.."
2025-11-17T09:41:43.445949391Z I1117 09:41:43.445882       1 schedule_one.go:889] "Unable to schedule pod; no fit; waiting" pod="openshift-oauth-apiserver/apiserver-59b5566b46-czsqx" err="0/5 nodes are available: 2 node(s) didn't match Pod's node affinity/selector, 3 node(s) didn't match pod anti-affinity rules. preemption: 0/5 nodes are available: 2 Preemption is not helpful for scheduling, 3 node(s) didn't match pod anti-affinity rules.."
2025-11-17T09:41:43.446499118Z I1117 09:41:43.446458       1 schedule_one.go:889] "Unable to schedule pod; no fit; waiting" pod="openshift-apiserver/apiserver-844688b4f5-gcqpj" err="0/5 nodes are available: 2 node(s) didn't match Pod's node affinity/selector, 3 node(s) didn't match pod anti-affinity rules. preemption: 0/5 nodes are available: 2 Preemption is not helpful for scheduling, 3 node(s) didn't match pod anti-affinity rules.."
2025-11-17T09:41:45.669967027Z I1117 09:41:45.669911       1 schedule_one.go:889] "Unable to schedule pod; no fit; waiting" pod="openshift-oauth-apiserver/apiserver-59b5566b46-czsqx" err="0/5 nodes are available: 2 node(s) didn't match Pod's node affinity/selector, 3 node(s) didn't match pod anti-affinity rules. preemption: 0/5 nodes are available: 2 Preemption is not helpful for scheduling, 3 node(s) didn't match pod anti-affinity rules.."
2025-11-17T09:41:45.670611274Z I1117 09:41:45.670567       1 schedule_one.go:889] "Unable to schedule pod; no fit; waiting" pod="openshift-apiserver/apiserver-844688b4f5-gcqpj" err="0/5 nodes are available: 2 node(s) didn't match Pod's node affinity/selector, 3 node(s) didn't match pod anti-affinity rules. preemption: 0/5 nodes are available: 2 Preemption is not helpful for scheduling, 3 node(s) didn't match pod anti-affinity rules.."
2025-11-17T09:41:54.385237566Z I1117 09:41:54.385185       1 schedule_one.go:889] "Unable to schedule pod; no fit; waiting" pod="openshift-oauth-apiserver/apiserver-59b5566b46-czsqx" err="0/5 nodes are available: 2 node(s) didn't match Pod's node affinity/selector, 3 node(s) didn't match pod anti-affinity rules. preemption: 0/5 nodes are available: 2 Preemption is not helpful for scheduling, 3 node(s) didn't match pod anti-affinity rules.."
2025-11-17T09:41:54.385823206Z I1117 09:41:54.385788       1 schedule_one.go:889] "Unable to schedule pod; no fit; waiting" pod="openshift-apiserver/apiserver-844688b4f5-gcqpj" err="0/5 nodes are available: 2 node(s) didn't match Pod's node affinity/selector, 3 node(s) didn't match pod anti-affinity rules. preemption: 0/5 nodes are available: 2 Preemption is not helpful for scheduling, 3 node(s) didn't match pod anti-affinity rules.."
2025-11-17T09:42:04.111839052Z I1117 09:42:04.111786       1 schedule_one.go:889] "Unable to schedule pod; no fit; waiting" pod="openshift-oauth-apiserver/apiserver-59b5566b46-czsqx" err="0/5 nodes are available: 2 node(s) didn't match Pod's node affinity/selector, 3 node(s) didn't match pod anti-affinity rules. preemption: 0/5 nodes are available: 2 Preemption is not helpful for scheduling, 3 node(s) didn't match pod anti-affinity rules.."
2025-11-17T09:42:04.112845290Z I1117 09:42:04.112796       1 schedule_one.go:889] "Unable to schedule pod; no fit; waiting" pod="openshift-apiserver/apiserver-844688b4f5-gcqpj" err="0/5 nodes are available: 2 node(s) didn't match Pod's node affinity/selector, 3 node(s) didn't match pod anti-affinity rules. preemption: 0/5 nodes are available: 2 Preemption is not helpful for scheduling, 3 node(s) didn't match pod anti-affinity rules.."
2025-11-17T09:42:26.405146536Z I1117 09:42:26.404179       1 schedule_one.go:889] "Unable to schedule pod; no fit; waiting" pod="openshift-apiserver/apiserver-844688b4f5-gcqpj" err="0/5 nodes are available: 2 node(s) didn't match Pod's node affinity/selector, 3 node(s) didn't match pod anti-affinity rules. preemption: 0/5 nodes are available: 2 Preemption is not helpful for scheduling, 3 node(s) didn't match pod anti-affinity rules.."
2025-11-17T09:42:26.416653506Z I1117 09:42:26.416610       1 schedule_one.go:252] "Successfully bound pod to node" pod="openshift-oauth-apiserver/apiserver-59b5566b46-czsqx" node="XXXXXX1" evaluatedNodes=5 feasibleNodes=1
2025-11-17T09:42:36.651457726Z I1117 09:42:36.651384       1 schedule_one.go:889] "Unable to schedule pod; no fit; waiting" pod="openshift-apiserver/apiserver-844688b4f5-gcqpj" err="0/5 nodes are available: 2 node(s) didn't match Pod's node affinity/selector, 3 node(s) didn't match pod anti-affinity rules. preemption: 0/5 nodes are available: 2 Preemption is not helpful for scheduling, 3 node(s) didn't match pod anti-affinity rules.."
2025-11-17T09:42:46.708324321Z I1117 09:42:46.708265       1 schedule_one.go:252] "Successfully bound pod to node" pod="openshift-apiserver/apiserver-844688b4f5-gcqpj" node="XXXXXX1" evaluatedNodes=5 feasibleNodes=1
2025-11-17T09:42:57.181892851Z I1117 09:42:57.181835       1 schedule_one.go:889] "Unable to schedule pod; no fit; waiting" pod="openshift-apiserver/apiserver-844688b4f5-h4tmn" err="0/5 nodes are available: 2 node(s) didn't match Pod's node affinity/selector, 3 node(s) didn't match pod anti-affinity rules. preemption: 0/5 nodes are available: 2 Preemption is not helpful for scheduling, 3 node(s) didn't match pod anti-affinity rules.."
2025-11-17T09:43:32.954485366Z I1117 09:43:32.952379       1 schedule_one.go:889] "Unable to schedule pod; no fit; waiting" pod="openshift-apiserver/apiserver-844688b4f5-h4tmn" err="0/5 nodes are available: 2 node(s) didn't match Pod's node affinity/selector, 3 node(s) didn't match pod anti-affinity rules. preemption: 0/5 nodes are available: 2 Preemption is not helpful for scheduling, 3 node(s) didn't match pod anti-affinity rules.."
2025-11-17T09:44:00.121682463Z I1117 09:44:00.121605       1 schedule_one.go:889] "Unable to schedule pod; no fit; waiting" pod="openshift-apiserver/apiserver-844688b4f5-h4tmn" err="0/5 nodes are available: 2 node(s) didn't match Pod's node affinity/selector, 3 node(s) didn't match pod anti-affinity rules. preemption: 0/5 nodes are available: 2 Preemption is not helpful for scheduling, 3 node(s) didn't match pod anti-affinity rules.."
2025-11-17T09:44:12.534182445Z I1117 09:44:12.533442       1 schedule_one.go:252] "Successfully bound pod to node" pod="openshift-apiserver/apiserver-844688b4f5-h4tmn" node="XXXXXX2" evaluatedNodes=5 feasibleNodes=1
2025-11-17T09:45:00.178199220Z I1117 09:45:00.178123       1 schedule_one.go:252] "Successfully bound pod to node" pod="openshift-operator-lifecycle-manager/collect-profiles-29389545-cj92b" node="XXXXXX1" evaluatedNodes=5 feasibleNodes=2
2025-11-17T09:46:54.126069263Z I1117 09:46:54.125902       1 schedule_one.go:252] "Successfully bound pod to node" pod="openshift-marketplace/community-operators-2qbss" node="XXXXXX1" evaluatedNodes=5 feasibleNodes=3
2025-11-17T09:46:54.127739345Z I1117 09:46:54.127681       1 schedule_one.go:252] "Successfully bound pod to node" pod="openshift-marketplace/certified-operators-t86tc" node="XXXXXX1" evaluatedNodes=5 feasibleNodes=3
2025-11-17T09:46:54.181072691Z I1117 09:46:54.181024       1 schedule_one.go:252] "Successfully bound pod to node" pod="openshift-marketplace/redhat-marketplace-9mch7" node="XXXXXX1" evaluatedNodes=5 feasibleNodes=3
2025-11-17T09:46:54.208962849Z I1117 09:46:54.208905       1 schedule_one.go:252] "Successfully bound pod to node" pod="openshift-marketplace/redhat-operators-9t5dt" node="XXXXXX1" evaluatedNodes=5 feasibleNodes=3
2025-11-17T09:51:31.981998351Z I1117 09:51:31.981860       1 schedule_one.go:252] "Successfully bound pod to node" pod="openshift-must-gather-cw8sn/must-gather-cpvtm" node="XXXXXX0" evaluatedNodes=5 feasibleNodes=3
